2025-07-08 10:56:07,100 ERROR scheduler Skipped queueing frappe.integrations.doctype.google_contacts.google_contacts.sync because it was found in queue for erp.amey.local
2025-07-08 10:56:07,156 ERROR scheduler Skipped queueing erpnext.setup.doctype.email_digest.email_digest.send because it was found in queue for erp.amey.local
2025-07-08 10:56:07,189 ERROR scheduler Skipped queueing erpnext.assets.doctype.asset.depreciation.post_depreciation_entries because it was found in queue for erp.amey.local
2025-07-08 10:56:07,216 ERROR scheduler Skipped queueing frappe.integrations.doctype.google_drive.google_drive.daily_backup because it was found in queue for erp.amey.local
2025-07-08 10:56:07,250 ERROR scheduler Skipped queueing frappe.oauth.delete_oauth2_data because it was found in queue for erp.amey.local
2025-07-08 10:56:07,271 ERROR scheduler Skipped queueing erpnext.utilities.bulk_transaction.retry because it was found in queue for erp.amey.local
2025-07-08 11:08:10,086 ERROR scheduler Exception in Enqueue Events for Site erp.amey.local
Traceback (most recent call last):
  File "/Users/amee/erpnext-bench/env/lib/python3.11/site-packages/redis/connection.py", line 861, in can_read
    return self._parser.can_read(timeout)
           ^^^^^^^^^^^^^^^^^^^^^^^^^^^^^^
  File "/Users/amee/erpnext-bench/env/lib/python3.11/site-packages/redis/connection.py", line 444, in can_read
    return self.read_from_socket(timeout=timeout, raise_on_timeout=False)
           ^^^^^^^^^^^^^^^^^^^^^^^^^^^^^^^^^^^^^^^^^^^^^^^^^^^^^^^^^^^^^^
  File "/Users/amee/erpnext-bench/env/lib/python3.11/site-packages/redis/connection.py", line 453, in read_from_socket
    bufflen = self._sock.recv_into(self._buffer)
              ^^^^^^^^^^^^^^^^^^^^^^^^^^^^^^^^^^
ConnectionResetError: [Errno 54] Connection reset by peer

During handling of the above exception, another exception occurred:

Traceback (most recent call last):
  File "/Users/amee/erpnext-bench/env/lib/python3.11/site-packages/redis/connection.py", line 1463, in get_connection
    if connection.can_read():
       ^^^^^^^^^^^^^^^^^^^^^
  File "/Users/amee/erpnext-bench/env/lib/python3.11/site-packages/redis/connection.py", line 864, in can_read
    raise ConnectionError(f"Error while reading from {host_error}: {e.args}")
redis.exceptions.ConnectionError: Error while reading from 127.0.0.1:11000: (54, 'Connection reset by peer')

During handling of the above exception, another exception occurred:

Traceback (most recent call last):
  File "/Users/amee/erpnext-bench/env/lib/python3.11/site-packages/redis/connection.py", line 699, in connect
    sock = self.retry.call_with_retry(
           ^^^^^^^^^^^^^^^^^^^^^^^^^^^
  File "/Users/amee/erpnext-bench/env/lib/python3.11/site-packages/redis/retry.py", line 46, in call_with_retry
    return do()
           ^^^^
  File "/Users/amee/erpnext-bench/env/lib/python3.11/site-packages/redis/connection.py", line 700, in <lambda>
    lambda: self._connect(), lambda error: self.disconnect(error)
            ^^^^^^^^^^^^^^^
  File "/Users/amee/erpnext-bench/env/lib/python3.11/site-packages/redis/connection.py", line 1002, in _connect
    raise err
  File "/Users/amee/erpnext-bench/env/lib/python3.11/site-packages/redis/connection.py", line 990, in _connect
    sock.connect(socket_address)
ConnectionRefusedError: [Errno 61] Connection refused

During handling of the above exception, another exception occurred:

Traceback (most recent call last):
  File "/Users/amee/erpnext-bench/apps/frappe/frappe/utils/scheduler.py", line 102, in enqueue_events_for_site
    enqueue_events(site=site)
  File "/Users/amee/erpnext-bench/apps/frappe/frappe/utils/scheduler.py", line 122, in enqueue_events
    if job_type.enqueue():
       ^^^^^^^^^^^^^^^^^^
  File "/Users/amee/erpnext-bench/apps/frappe/frappe/core/doctype/scheduled_job_type/scheduled_job_type.py", line 74, in enqueue
    if not self.is_job_in_queue():
           ^^^^^^^^^^^^^^^^^^^^^^
  File "/Users/amee/erpnext-bench/apps/frappe/frappe/core/doctype/scheduled_job_type/scheduled_job_type.py", line 95, in is_job_in_queue
    return is_job_enqueued(self.rq_job_id)
           ^^^^^^^^^^^^^^^^^^^^^^^^^^^^^^^
  File "/Users/amee/erpnext-bench/apps/frappe/frappe/utils/background_jobs.py", line 568, in is_job_enqueued
    return get_job_status(job_id) in (JobStatus.QUEUED, JobStatus.STARTED)
           ^^^^^^^^^^^^^^^^^^^^^^
  File "/Users/amee/erpnext-bench/apps/frappe/frappe/utils/background_jobs.py", line 573, in get_job_status
    job = get_job(job_id)
          ^^^^^^^^^^^^^^^
  File "/Users/amee/erpnext-bench/apps/frappe/frappe/utils/background_jobs.py", line 580, in get_job
    return Job.fetch(create_job_id(job_id), connection=get_redis_conn())
           ^^^^^^^^^^^^^^^^^^^^^^^^^^^^^^^^^^^^^^^^^^^^^^^^^^^^^^^^^^^^^
  File "/Users/amee/erpnext-bench/env/lib/python3.11/site-packages/rq/job.py", line 591, in fetch
    job.refresh()
  File "/Users/amee/erpnext-bench/env/lib/python3.11/site-packages/rq/job.py", line 989, in refresh
    data = self.connection.hgetall(self.key)
           ^^^^^^^^^^^^^^^^^^^^^^^^^^^^^^^^^
  File "/Users/amee/erpnext-bench/env/lib/python3.11/site-packages/redis/commands/core.py", line 4887, in hgetall
    return self.execute_command("HGETALL", name)
           ^^^^^^^^^^^^^^^^^^^^^^^^^^^^^^^^^^^^^
  File "/Users/amee/erpnext-bench/env/lib/python3.11/site-packages/redis/client.py", line 1266, in execute_command
    conn = self.connection or pool.get_connection(command_name, **options)
                              ^^^^^^^^^^^^^^^^^^^^^^^^^^^^^^^^^^^^^^^^^^^^
  File "/Users/amee/erpnext-bench/env/lib/python3.11/site-packages/redis/connection.py", line 1467, in get_connection
    connection.connect()
  File "/Users/amee/erpnext-bench/env/lib/python3.11/site-packages/redis/connection.py", line 705, in connect
    raise ConnectionError(self._error_message(e))
redis.exceptions.ConnectionError: Error 61 connecting to 127.0.0.1:11000. Connection refused.
2025-07-08 11:09:10,340 ERROR scheduler Exception in Enqueue Events for Site erp.amey.local
Traceback (most recent call last):
  File "/Users/amee/erpnext-bench/env/lib/python3.11/site-packages/redis/connection.py", line 699, in connect
    sock = self.retry.call_with_retry(
           ^^^^^^^^^^^^^^^^^^^^^^^^^^^
  File "/Users/amee/erpnext-bench/env/lib/python3.11/site-packages/redis/retry.py", line 46, in call_with_retry
    return do()
           ^^^^
  File "/Users/amee/erpnext-bench/env/lib/python3.11/site-packages/redis/connection.py", line 700, in <lambda>
    lambda: self._connect(), lambda error: self.disconnect(error)
            ^^^^^^^^^^^^^^^
  File "/Users/amee/erpnext-bench/env/lib/python3.11/site-packages/redis/connection.py", line 1002, in _connect
    raise err
  File "/Users/amee/erpnext-bench/env/lib/python3.11/site-packages/redis/connection.py", line 990, in _connect
    sock.connect(socket_address)
ConnectionRefusedError: [Errno 61] Connection refused

During handling of the above exception, another exception occurred:

Traceback (most recent call last):
  File "/Users/amee/erpnext-bench/apps/frappe/frappe/utils/scheduler.py", line 102, in enqueue_events_for_site
    enqueue_events(site=site)
  File "/Users/amee/erpnext-bench/apps/frappe/frappe/utils/scheduler.py", line 122, in enqueue_events
    if job_type.enqueue():
       ^^^^^^^^^^^^^^^^^^
  File "/Users/amee/erpnext-bench/apps/frappe/frappe/core/doctype/scheduled_job_type/scheduled_job_type.py", line 74, in enqueue
    if not self.is_job_in_queue():
           ^^^^^^^^^^^^^^^^^^^^^^
  File "/Users/amee/erpnext-bench/apps/frappe/frappe/core/doctype/scheduled_job_type/scheduled_job_type.py", line 95, in is_job_in_queue
    return is_job_enqueued(self.rq_job_id)
           ^^^^^^^^^^^^^^^^^^^^^^^^^^^^^^^
  File "/Users/amee/erpnext-bench/apps/frappe/frappe/utils/background_jobs.py", line 568, in is_job_enqueued
    return get_job_status(job_id) in (JobStatus.QUEUED, JobStatus.STARTED)
           ^^^^^^^^^^^^^^^^^^^^^^
  File "/Users/amee/erpnext-bench/apps/frappe/frappe/utils/background_jobs.py", line 573, in get_job_status
    job = get_job(job_id)
          ^^^^^^^^^^^^^^^
  File "/Users/amee/erpnext-bench/apps/frappe/frappe/utils/background_jobs.py", line 580, in get_job
    return Job.fetch(create_job_id(job_id), connection=get_redis_conn())
           ^^^^^^^^^^^^^^^^^^^^^^^^^^^^^^^^^^^^^^^^^^^^^^^^^^^^^^^^^^^^^
  File "/Users/amee/erpnext-bench/env/lib/python3.11/site-packages/rq/job.py", line 591, in fetch
    job.refresh()
  File "/Users/amee/erpnext-bench/env/lib/python3.11/site-packages/rq/job.py", line 989, in refresh
    data = self.connection.hgetall(self.key)
           ^^^^^^^^^^^^^^^^^^^^^^^^^^^^^^^^^
  File "/Users/amee/erpnext-bench/env/lib/python3.11/site-packages/redis/commands/core.py", line 4887, in hgetall
    return self.execute_command("HGETALL", name)
           ^^^^^^^^^^^^^^^^^^^^^^^^^^^^^^^^^^^^^
  File "/Users/amee/erpnext-bench/env/lib/python3.11/site-packages/redis/client.py", line 1266, in execute_command
    conn = self.connection or pool.get_connection(command_name, **options)
                              ^^^^^^^^^^^^^^^^^^^^^^^^^^^^^^^^^^^^^^^^^^^^
  File "/Users/amee/erpnext-bench/env/lib/python3.11/site-packages/redis/connection.py", line 1457, in get_connection
    connection.connect()
  File "/Users/amee/erpnext-bench/env/lib/python3.11/site-packages/redis/connection.py", line 705, in connect
    raise ConnectionError(self._error_message(e))
redis.exceptions.ConnectionError: Error 61 connecting to 127.0.0.1:11000. Connection refused.
2025-07-08 11:10:10,776 ERROR scheduler Exception in Enqueue Events for Site erp.amey.local
Traceback (most recent call last):
  File "/Users/amee/erpnext-bench/env/lib/python3.11/site-packages/redis/connection.py", line 699, in connect
    sock = self.retry.call_with_retry(
           ^^^^^^^^^^^^^^^^^^^^^^^^^^^
  File "/Users/amee/erpnext-bench/env/lib/python3.11/site-packages/redis/retry.py", line 46, in call_with_retry
    return do()
           ^^^^
  File "/Users/amee/erpnext-bench/env/lib/python3.11/site-packages/redis/connection.py", line 700, in <lambda>
    lambda: self._connect(), lambda error: self.disconnect(error)
            ^^^^^^^^^^^^^^^
  File "/Users/amee/erpnext-bench/env/lib/python3.11/site-packages/redis/connection.py", line 1002, in _connect
    raise err
  File "/Users/amee/erpnext-bench/env/lib/python3.11/site-packages/redis/connection.py", line 990, in _connect
    sock.connect(socket_address)
ConnectionRefusedError: [Errno 61] Connection refused

During handling of the above exception, another exception occurred:

Traceback (most recent call last):
  File "/Users/amee/erpnext-bench/apps/frappe/frappe/utils/scheduler.py", line 102, in enqueue_events_for_site
    enqueue_events(site=site)
  File "/Users/amee/erpnext-bench/apps/frappe/frappe/utils/scheduler.py", line 122, in enqueue_events
    if job_type.enqueue():
       ^^^^^^^^^^^^^^^^^^
  File "/Users/amee/erpnext-bench/apps/frappe/frappe/core/doctype/scheduled_job_type/scheduled_job_type.py", line 74, in enqueue
    if not self.is_job_in_queue():
           ^^^^^^^^^^^^^^^^^^^^^^
  File "/Users/amee/erpnext-bench/apps/frappe/frappe/core/doctype/scheduled_job_type/scheduled_job_type.py", line 95, in is_job_in_queue
    return is_job_enqueued(self.rq_job_id)
           ^^^^^^^^^^^^^^^^^^^^^^^^^^^^^^^
  File "/Users/amee/erpnext-bench/apps/frappe/frappe/utils/background_jobs.py", line 568, in is_job_enqueued
    return get_job_status(job_id) in (JobStatus.QUEUED, JobStatus.STARTED)
           ^^^^^^^^^^^^^^^^^^^^^^
  File "/Users/amee/erpnext-bench/apps/frappe/frappe/utils/background_jobs.py", line 573, in get_job_status
    job = get_job(job_id)
          ^^^^^^^^^^^^^^^
  File "/Users/amee/erpnext-bench/apps/frappe/frappe/utils/background_jobs.py", line 580, in get_job
    return Job.fetch(create_job_id(job_id), connection=get_redis_conn())
           ^^^^^^^^^^^^^^^^^^^^^^^^^^^^^^^^^^^^^^^^^^^^^^^^^^^^^^^^^^^^^
  File "/Users/amee/erpnext-bench/env/lib/python3.11/site-packages/rq/job.py", line 591, in fetch
    job.refresh()
  File "/Users/amee/erpnext-bench/env/lib/python3.11/site-packages/rq/job.py", line 989, in refresh
    data = self.connection.hgetall(self.key)
           ^^^^^^^^^^^^^^^^^^^^^^^^^^^^^^^^^
  File "/Users/amee/erpnext-bench/env/lib/python3.11/site-packages/redis/commands/core.py", line 4887, in hgetall
    return self.execute_command("HGETALL", name)
           ^^^^^^^^^^^^^^^^^^^^^^^^^^^^^^^^^^^^^
  File "/Users/amee/erpnext-bench/env/lib/python3.11/site-packages/redis/client.py", line 1266, in execute_command
    conn = self.connection or pool.get_connection(command_name, **options)
                              ^^^^^^^^^^^^^^^^^^^^^^^^^^^^^^^^^^^^^^^^^^^^
  File "/Users/amee/erpnext-bench/env/lib/python3.11/site-packages/redis/connection.py", line 1457, in get_connection
    connection.connect()
  File "/Users/amee/erpnext-bench/env/lib/python3.11/site-packages/redis/connection.py", line 705, in connect
    raise ConnectionError(self._error_message(e))
redis.exceptions.ConnectionError: Error 61 connecting to 127.0.0.1:11000. Connection refused.
2025-07-08 11:11:11,233 ERROR scheduler Exception in Enqueue Events for Site erp.amey.local
Traceback (most recent call last):
  File "/Users/amee/erpnext-bench/env/lib/python3.11/site-packages/redis/connection.py", line 699, in connect
    sock = self.retry.call_with_retry(
           ^^^^^^^^^^^^^^^^^^^^^^^^^^^
  File "/Users/amee/erpnext-bench/env/lib/python3.11/site-packages/redis/retry.py", line 46, in call_with_retry
    return do()
           ^^^^
  File "/Users/amee/erpnext-bench/env/lib/python3.11/site-packages/redis/connection.py", line 700, in <lambda>
    lambda: self._connect(), lambda error: self.disconnect(error)
            ^^^^^^^^^^^^^^^
  File "/Users/amee/erpnext-bench/env/lib/python3.11/site-packages/redis/connection.py", line 1002, in _connect
    raise err
  File "/Users/amee/erpnext-bench/env/lib/python3.11/site-packages/redis/connection.py", line 990, in _connect
    sock.connect(socket_address)
ConnectionRefusedError: [Errno 61] Connection refused

During handling of the above exception, another exception occurred:

Traceback (most recent call last):
  File "/Users/amee/erpnext-bench/apps/frappe/frappe/utils/scheduler.py", line 102, in enqueue_events_for_site
    enqueue_events(site=site)
  File "/Users/amee/erpnext-bench/apps/frappe/frappe/utils/scheduler.py", line 122, in enqueue_events
    if job_type.enqueue():
       ^^^^^^^^^^^^^^^^^^
  File "/Users/amee/erpnext-bench/apps/frappe/frappe/core/doctype/scheduled_job_type/scheduled_job_type.py", line 74, in enqueue
    if not self.is_job_in_queue():
           ^^^^^^^^^^^^^^^^^^^^^^
  File "/Users/amee/erpnext-bench/apps/frappe/frappe/core/doctype/scheduled_job_type/scheduled_job_type.py", line 95, in is_job_in_queue
    return is_job_enqueued(self.rq_job_id)
           ^^^^^^^^^^^^^^^^^^^^^^^^^^^^^^^
  File "/Users/amee/erpnext-bench/apps/frappe/frappe/utils/background_jobs.py", line 568, in is_job_enqueued
    return get_job_status(job_id) in (JobStatus.QUEUED, JobStatus.STARTED)
           ^^^^^^^^^^^^^^^^^^^^^^
  File "/Users/amee/erpnext-bench/apps/frappe/frappe/utils/background_jobs.py", line 573, in get_job_status
    job = get_job(job_id)
          ^^^^^^^^^^^^^^^
  File "/Users/amee/erpnext-bench/apps/frappe/frappe/utils/background_jobs.py", line 580, in get_job
    return Job.fetch(create_job_id(job_id), connection=get_redis_conn())
           ^^^^^^^^^^^^^^^^^^^^^^^^^^^^^^^^^^^^^^^^^^^^^^^^^^^^^^^^^^^^^
  File "/Users/amee/erpnext-bench/env/lib/python3.11/site-packages/rq/job.py", line 591, in fetch
    job.refresh()
  File "/Users/amee/erpnext-bench/env/lib/python3.11/site-packages/rq/job.py", line 989, in refresh
    data = self.connection.hgetall(self.key)
           ^^^^^^^^^^^^^^^^^^^^^^^^^^^^^^^^^
  File "/Users/amee/erpnext-bench/env/lib/python3.11/site-packages/redis/commands/core.py", line 4887, in hgetall
    return self.execute_command("HGETALL", name)
           ^^^^^^^^^^^^^^^^^^^^^^^^^^^^^^^^^^^^^
  File "/Users/amee/erpnext-bench/env/lib/python3.11/site-packages/redis/client.py", line 1266, in execute_command
    conn = self.connection or pool.get_connection(command_name, **options)
                              ^^^^^^^^^^^^^^^^^^^^^^^^^^^^^^^^^^^^^^^^^^^^
  File "/Users/amee/erpnext-bench/env/lib/python3.11/site-packages/redis/connection.py", line 1457, in get_connection
    connection.connect()
  File "/Users/amee/erpnext-bench/env/lib/python3.11/site-packages/redis/connection.py", line 705, in connect
    raise ConnectionError(self._error_message(e))
redis.exceptions.ConnectionError: Error 61 connecting to 127.0.0.1:11000. Connection refused.
2025-07-08 11:12:11,416 ERROR scheduler Exception in Enqueue Events for Site erp.amey.local
Traceback (most recent call last):
  File "/Users/amee/erpnext-bench/env/lib/python3.11/site-packages/redis/connection.py", line 699, in connect
    sock = self.retry.call_with_retry(
           ^^^^^^^^^^^^^^^^^^^^^^^^^^^
  File "/Users/amee/erpnext-bench/env/lib/python3.11/site-packages/redis/retry.py", line 46, in call_with_retry
    return do()
           ^^^^
  File "/Users/amee/erpnext-bench/env/lib/python3.11/site-packages/redis/connection.py", line 700, in <lambda>
    lambda: self._connect(), lambda error: self.disconnect(error)
            ^^^^^^^^^^^^^^^
  File "/Users/amee/erpnext-bench/env/lib/python3.11/site-packages/redis/connection.py", line 1002, in _connect
    raise err
  File "/Users/amee/erpnext-bench/env/lib/python3.11/site-packages/redis/connection.py", line 990, in _connect
    sock.connect(socket_address)
ConnectionRefusedError: [Errno 61] Connection refused

During handling of the above exception, another exception occurred:

Traceback (most recent call last):
  File "/Users/amee/erpnext-bench/apps/frappe/frappe/utils/scheduler.py", line 102, in enqueue_events_for_site
    enqueue_events(site=site)
  File "/Users/amee/erpnext-bench/apps/frappe/frappe/utils/scheduler.py", line 122, in enqueue_events
    if job_type.enqueue():
       ^^^^^^^^^^^^^^^^^^
  File "/Users/amee/erpnext-bench/apps/frappe/frappe/core/doctype/scheduled_job_type/scheduled_job_type.py", line 74, in enqueue
    if not self.is_job_in_queue():
           ^^^^^^^^^^^^^^^^^^^^^^
  File "/Users/amee/erpnext-bench/apps/frappe/frappe/core/doctype/scheduled_job_type/scheduled_job_type.py", line 95, in is_job_in_queue
    return is_job_enqueued(self.rq_job_id)
           ^^^^^^^^^^^^^^^^^^^^^^^^^^^^^^^
  File "/Users/amee/erpnext-bench/apps/frappe/frappe/utils/background_jobs.py", line 568, in is_job_enqueued
    return get_job_status(job_id) in (JobStatus.QUEUED, JobStatus.STARTED)
           ^^^^^^^^^^^^^^^^^^^^^^
  File "/Users/amee/erpnext-bench/apps/frappe/frappe/utils/background_jobs.py", line 573, in get_job_status
    job = get_job(job_id)
          ^^^^^^^^^^^^^^^
  File "/Users/amee/erpnext-bench/apps/frappe/frappe/utils/background_jobs.py", line 580, in get_job
    return Job.fetch(create_job_id(job_id), connection=get_redis_conn())
           ^^^^^^^^^^^^^^^^^^^^^^^^^^^^^^^^^^^^^^^^^^^^^^^^^^^^^^^^^^^^^
  File "/Users/amee/erpnext-bench/env/lib/python3.11/site-packages/rq/job.py", line 591, in fetch
    job.refresh()
  File "/Users/amee/erpnext-bench/env/lib/python3.11/site-packages/rq/job.py", line 989, in refresh
    data = self.connection.hgetall(self.key)
           ^^^^^^^^^^^^^^^^^^^^^^^^^^^^^^^^^
  File "/Users/amee/erpnext-bench/env/lib/python3.11/site-packages/redis/commands/core.py", line 4887, in hgetall
    return self.execute_command("HGETALL", name)
           ^^^^^^^^^^^^^^^^^^^^^^^^^^^^^^^^^^^^^
  File "/Users/amee/erpnext-bench/env/lib/python3.11/site-packages/redis/client.py", line 1266, in execute_command
    conn = self.connection or pool.get_connection(command_name, **options)
                              ^^^^^^^^^^^^^^^^^^^^^^^^^^^^^^^^^^^^^^^^^^^^
  File "/Users/amee/erpnext-bench/env/lib/python3.11/site-packages/redis/connection.py", line 1457, in get_connection
    connection.connect()
  File "/Users/amee/erpnext-bench/env/lib/python3.11/site-packages/redis/connection.py", line 705, in connect
    raise ConnectionError(self._error_message(e))
redis.exceptions.ConnectionError: Error 61 connecting to 127.0.0.1:11000. Connection refused.
2025-07-08 11:13:11,617 ERROR scheduler Exception in Enqueue Events for Site erp.amey.local
Traceback (most recent call last):
  File "/Users/amee/erpnext-bench/env/lib/python3.11/site-packages/redis/connection.py", line 699, in connect
    sock = self.retry.call_with_retry(
           ^^^^^^^^^^^^^^^^^^^^^^^^^^^
  File "/Users/amee/erpnext-bench/env/lib/python3.11/site-packages/redis/retry.py", line 46, in call_with_retry
    return do()
           ^^^^
  File "/Users/amee/erpnext-bench/env/lib/python3.11/site-packages/redis/connection.py", line 700, in <lambda>
    lambda: self._connect(), lambda error: self.disconnect(error)
            ^^^^^^^^^^^^^^^
  File "/Users/amee/erpnext-bench/env/lib/python3.11/site-packages/redis/connection.py", line 1002, in _connect
    raise err
  File "/Users/amee/erpnext-bench/env/lib/python3.11/site-packages/redis/connection.py", line 990, in _connect
    sock.connect(socket_address)
ConnectionRefusedError: [Errno 61] Connection refused

During handling of the above exception, another exception occurred:

Traceback (most recent call last):
  File "/Users/amee/erpnext-bench/apps/frappe/frappe/utils/scheduler.py", line 102, in enqueue_events_for_site
    enqueue_events(site=site)
  File "/Users/amee/erpnext-bench/apps/frappe/frappe/utils/scheduler.py", line 122, in enqueue_events
    if job_type.enqueue():
       ^^^^^^^^^^^^^^^^^^
  File "/Users/amee/erpnext-bench/apps/frappe/frappe/core/doctype/scheduled_job_type/scheduled_job_type.py", line 74, in enqueue
    if not self.is_job_in_queue():
           ^^^^^^^^^^^^^^^^^^^^^^
  File "/Users/amee/erpnext-bench/apps/frappe/frappe/core/doctype/scheduled_job_type/scheduled_job_type.py", line 95, in is_job_in_queue
    return is_job_enqueued(self.rq_job_id)
           ^^^^^^^^^^^^^^^^^^^^^^^^^^^^^^^
  File "/Users/amee/erpnext-bench/apps/frappe/frappe/utils/background_jobs.py", line 568, in is_job_enqueued
    return get_job_status(job_id) in (JobStatus.QUEUED, JobStatus.STARTED)
           ^^^^^^^^^^^^^^^^^^^^^^
  File "/Users/amee/erpnext-bench/apps/frappe/frappe/utils/background_jobs.py", line 573, in get_job_status
    job = get_job(job_id)
          ^^^^^^^^^^^^^^^
  File "/Users/amee/erpnext-bench/apps/frappe/frappe/utils/background_jobs.py", line 580, in get_job
    return Job.fetch(create_job_id(job_id), connection=get_redis_conn())
           ^^^^^^^^^^^^^^^^^^^^^^^^^^^^^^^^^^^^^^^^^^^^^^^^^^^^^^^^^^^^^
  File "/Users/amee/erpnext-bench/env/lib/python3.11/site-packages/rq/job.py", line 591, in fetch
    job.refresh()
  File "/Users/amee/erpnext-bench/env/lib/python3.11/site-packages/rq/job.py", line 989, in refresh
    data = self.connection.hgetall(self.key)
           ^^^^^^^^^^^^^^^^^^^^^^^^^^^^^^^^^
  File "/Users/amee/erpnext-bench/env/lib/python3.11/site-packages/redis/commands/core.py", line 4887, in hgetall
    return self.execute_command("HGETALL", name)
           ^^^^^^^^^^^^^^^^^^^^^^^^^^^^^^^^^^^^^
  File "/Users/amee/erpnext-bench/env/lib/python3.11/site-packages/redis/client.py", line 1266, in execute_command
    conn = self.connection or pool.get_connection(command_name, **options)
                              ^^^^^^^^^^^^^^^^^^^^^^^^^^^^^^^^^^^^^^^^^^^^
  File "/Users/amee/erpnext-bench/env/lib/python3.11/site-packages/redis/connection.py", line 1457, in get_connection
    connection.connect()
  File "/Users/amee/erpnext-bench/env/lib/python3.11/site-packages/redis/connection.py", line 705, in connect
    raise ConnectionError(self._error_message(e))
redis.exceptions.ConnectionError: Error 61 connecting to 127.0.0.1:11000. Connection refused.
2025-07-08 11:14:11,812 ERROR scheduler Exception in Enqueue Events for Site erp.amey.local
Traceback (most recent call last):
  File "/Users/amee/erpnext-bench/env/lib/python3.11/site-packages/redis/connection.py", line 699, in connect
    sock = self.retry.call_with_retry(
           ^^^^^^^^^^^^^^^^^^^^^^^^^^^
  File "/Users/amee/erpnext-bench/env/lib/python3.11/site-packages/redis/retry.py", line 46, in call_with_retry
    return do()
           ^^^^
  File "/Users/amee/erpnext-bench/env/lib/python3.11/site-packages/redis/connection.py", line 700, in <lambda>
    lambda: self._connect(), lambda error: self.disconnect(error)
            ^^^^^^^^^^^^^^^
  File "/Users/amee/erpnext-bench/env/lib/python3.11/site-packages/redis/connection.py", line 1002, in _connect
    raise err
  File "/Users/amee/erpnext-bench/env/lib/python3.11/site-packages/redis/connection.py", line 990, in _connect
    sock.connect(socket_address)
ConnectionRefusedError: [Errno 61] Connection refused

During handling of the above exception, another exception occurred:

Traceback (most recent call last):
  File "/Users/amee/erpnext-bench/apps/frappe/frappe/utils/scheduler.py", line 102, in enqueue_events_for_site
    enqueue_events(site=site)
  File "/Users/amee/erpnext-bench/apps/frappe/frappe/utils/scheduler.py", line 122, in enqueue_events
    if job_type.enqueue():
       ^^^^^^^^^^^^^^^^^^
  File "/Users/amee/erpnext-bench/apps/frappe/frappe/core/doctype/scheduled_job_type/scheduled_job_type.py", line 74, in enqueue
    if not self.is_job_in_queue():
           ^^^^^^^^^^^^^^^^^^^^^^
  File "/Users/amee/erpnext-bench/apps/frappe/frappe/core/doctype/scheduled_job_type/scheduled_job_type.py", line 95, in is_job_in_queue
    return is_job_enqueued(self.rq_job_id)
           ^^^^^^^^^^^^^^^^^^^^^^^^^^^^^^^
  File "/Users/amee/erpnext-bench/apps/frappe/frappe/utils/background_jobs.py", line 568, in is_job_enqueued
    return get_job_status(job_id) in (JobStatus.QUEUED, JobStatus.STARTED)
           ^^^^^^^^^^^^^^^^^^^^^^
  File "/Users/amee/erpnext-bench/apps/frappe/frappe/utils/background_jobs.py", line 573, in get_job_status
    job = get_job(job_id)
          ^^^^^^^^^^^^^^^
  File "/Users/amee/erpnext-bench/apps/frappe/frappe/utils/background_jobs.py", line 580, in get_job
    return Job.fetch(create_job_id(job_id), connection=get_redis_conn())
           ^^^^^^^^^^^^^^^^^^^^^^^^^^^^^^^^^^^^^^^^^^^^^^^^^^^^^^^^^^^^^
  File "/Users/amee/erpnext-bench/env/lib/python3.11/site-packages/rq/job.py", line 591, in fetch
    job.refresh()
  File "/Users/amee/erpnext-bench/env/lib/python3.11/site-packages/rq/job.py", line 989, in refresh
    data = self.connection.hgetall(self.key)
           ^^^^^^^^^^^^^^^^^^^^^^^^^^^^^^^^^
  File "/Users/amee/erpnext-bench/env/lib/python3.11/site-packages/redis/commands/core.py", line 4887, in hgetall
    return self.execute_command("HGETALL", name)
           ^^^^^^^^^^^^^^^^^^^^^^^^^^^^^^^^^^^^^
  File "/Users/amee/erpnext-bench/env/lib/python3.11/site-packages/redis/client.py", line 1266, in execute_command
    conn = self.connection or pool.get_connection(command_name, **options)
                              ^^^^^^^^^^^^^^^^^^^^^^^^^^^^^^^^^^^^^^^^^^^^
  File "/Users/amee/erpnext-bench/env/lib/python3.11/site-packages/redis/connection.py", line 1457, in get_connection
    connection.connect()
  File "/Users/amee/erpnext-bench/env/lib/python3.11/site-packages/redis/connection.py", line 705, in connect
    raise ConnectionError(self._error_message(e))
redis.exceptions.ConnectionError: Error 61 connecting to 127.0.0.1:11000. Connection refused.
2025-07-08 11:15:12,043 ERROR scheduler Exception in Enqueue Events for Site erp.amey.local
Traceback (most recent call last):
  File "/Users/amee/erpnext-bench/env/lib/python3.11/site-packages/redis/connection.py", line 699, in connect
    sock = self.retry.call_with_retry(
           ^^^^^^^^^^^^^^^^^^^^^^^^^^^
  File "/Users/amee/erpnext-bench/env/lib/python3.11/site-packages/redis/retry.py", line 46, in call_with_retry
    return do()
           ^^^^
  File "/Users/amee/erpnext-bench/env/lib/python3.11/site-packages/redis/connection.py", line 700, in <lambda>
    lambda: self._connect(), lambda error: self.disconnect(error)
            ^^^^^^^^^^^^^^^
  File "/Users/amee/erpnext-bench/env/lib/python3.11/site-packages/redis/connection.py", line 1002, in _connect
    raise err
  File "/Users/amee/erpnext-bench/env/lib/python3.11/site-packages/redis/connection.py", line 990, in _connect
    sock.connect(socket_address)
ConnectionRefusedError: [Errno 61] Connection refused

During handling of the above exception, another exception occurred:

Traceback (most recent call last):
  File "/Users/amee/erpnext-bench/apps/frappe/frappe/utils/scheduler.py", line 102, in enqueue_events_for_site
    enqueue_events(site=site)
  File "/Users/amee/erpnext-bench/apps/frappe/frappe/utils/scheduler.py", line 122, in enqueue_events
    if job_type.enqueue():
       ^^^^^^^^^^^^^^^^^^
  File "/Users/amee/erpnext-bench/apps/frappe/frappe/core/doctype/scheduled_job_type/scheduled_job_type.py", line 74, in enqueue
    if not self.is_job_in_queue():
           ^^^^^^^^^^^^^^^^^^^^^^
  File "/Users/amee/erpnext-bench/apps/frappe/frappe/core/doctype/scheduled_job_type/scheduled_job_type.py", line 95, in is_job_in_queue
    return is_job_enqueued(self.rq_job_id)
           ^^^^^^^^^^^^^^^^^^^^^^^^^^^^^^^
  File "/Users/amee/erpnext-bench/apps/frappe/frappe/utils/background_jobs.py", line 568, in is_job_enqueued
    return get_job_status(job_id) in (JobStatus.QUEUED, JobStatus.STARTED)
           ^^^^^^^^^^^^^^^^^^^^^^
  File "/Users/amee/erpnext-bench/apps/frappe/frappe/utils/background_jobs.py", line 573, in get_job_status
    job = get_job(job_id)
          ^^^^^^^^^^^^^^^
  File "/Users/amee/erpnext-bench/apps/frappe/frappe/utils/background_jobs.py", line 580, in get_job
    return Job.fetch(create_job_id(job_id), connection=get_redis_conn())
           ^^^^^^^^^^^^^^^^^^^^^^^^^^^^^^^^^^^^^^^^^^^^^^^^^^^^^^^^^^^^^
  File "/Users/amee/erpnext-bench/env/lib/python3.11/site-packages/rq/job.py", line 591, in fetch
    job.refresh()
  File "/Users/amee/erpnext-bench/env/lib/python3.11/site-packages/rq/job.py", line 989, in refresh
    data = self.connection.hgetall(self.key)
           ^^^^^^^^^^^^^^^^^^^^^^^^^^^^^^^^^
  File "/Users/amee/erpnext-bench/env/lib/python3.11/site-packages/redis/commands/core.py", line 4887, in hgetall
    return self.execute_command("HGETALL", name)
           ^^^^^^^^^^^^^^^^^^^^^^^^^^^^^^^^^^^^^
  File "/Users/amee/erpnext-bench/env/lib/python3.11/site-packages/redis/client.py", line 1266, in execute_command
    conn = self.connection or pool.get_connection(command_name, **options)
                              ^^^^^^^^^^^^^^^^^^^^^^^^^^^^^^^^^^^^^^^^^^^^
  File "/Users/amee/erpnext-bench/env/lib/python3.11/site-packages/redis/connection.py", line 1457, in get_connection
    connection.connect()
  File "/Users/amee/erpnext-bench/env/lib/python3.11/site-packages/redis/connection.py", line 705, in connect
    raise ConnectionError(self._error_message(e))
redis.exceptions.ConnectionError: Error 61 connecting to 127.0.0.1:11000. Connection refused.
2025-07-08 11:16:12,259 ERROR scheduler Exception in Enqueue Events for Site erp.amey.local
Traceback (most recent call last):
  File "/Users/amee/erpnext-bench/env/lib/python3.11/site-packages/redis/connection.py", line 699, in connect
    sock = self.retry.call_with_retry(
           ^^^^^^^^^^^^^^^^^^^^^^^^^^^
  File "/Users/amee/erpnext-bench/env/lib/python3.11/site-packages/redis/retry.py", line 46, in call_with_retry
    return do()
           ^^^^
  File "/Users/amee/erpnext-bench/env/lib/python3.11/site-packages/redis/connection.py", line 700, in <lambda>
    lambda: self._connect(), lambda error: self.disconnect(error)
            ^^^^^^^^^^^^^^^
  File "/Users/amee/erpnext-bench/env/lib/python3.11/site-packages/redis/connection.py", line 1002, in _connect
    raise err
  File "/Users/amee/erpnext-bench/env/lib/python3.11/site-packages/redis/connection.py", line 990, in _connect
    sock.connect(socket_address)
ConnectionRefusedError: [Errno 61] Connection refused

During handling of the above exception, another exception occurred:

Traceback (most recent call last):
  File "/Users/amee/erpnext-bench/apps/frappe/frappe/utils/scheduler.py", line 102, in enqueue_events_for_site
    enqueue_events(site=site)
  File "/Users/amee/erpnext-bench/apps/frappe/frappe/utils/scheduler.py", line 122, in enqueue_events
    if job_type.enqueue():
       ^^^^^^^^^^^^^^^^^^
  File "/Users/amee/erpnext-bench/apps/frappe/frappe/core/doctype/scheduled_job_type/scheduled_job_type.py", line 74, in enqueue
    if not self.is_job_in_queue():
           ^^^^^^^^^^^^^^^^^^^^^^
  File "/Users/amee/erpnext-bench/apps/frappe/frappe/core/doctype/scheduled_job_type/scheduled_job_type.py", line 95, in is_job_in_queue
    return is_job_enqueued(self.rq_job_id)
           ^^^^^^^^^^^^^^^^^^^^^^^^^^^^^^^
  File "/Users/amee/erpnext-bench/apps/frappe/frappe/utils/background_jobs.py", line 568, in is_job_enqueued
    return get_job_status(job_id) in (JobStatus.QUEUED, JobStatus.STARTED)
           ^^^^^^^^^^^^^^^^^^^^^^
  File "/Users/amee/erpnext-bench/apps/frappe/frappe/utils/background_jobs.py", line 573, in get_job_status
    job = get_job(job_id)
          ^^^^^^^^^^^^^^^
  File "/Users/amee/erpnext-bench/apps/frappe/frappe/utils/background_jobs.py", line 580, in get_job
    return Job.fetch(create_job_id(job_id), connection=get_redis_conn())
           ^^^^^^^^^^^^^^^^^^^^^^^^^^^^^^^^^^^^^^^^^^^^^^^^^^^^^^^^^^^^^
  File "/Users/amee/erpnext-bench/env/lib/python3.11/site-packages/rq/job.py", line 591, in fetch
    job.refresh()
  File "/Users/amee/erpnext-bench/env/lib/python3.11/site-packages/rq/job.py", line 989, in refresh
    data = self.connection.hgetall(self.key)
           ^^^^^^^^^^^^^^^^^^^^^^^^^^^^^^^^^
  File "/Users/amee/erpnext-bench/env/lib/python3.11/site-packages/redis/commands/core.py", line 4887, in hgetall
    return self.execute_command("HGETALL", name)
           ^^^^^^^^^^^^^^^^^^^^^^^^^^^^^^^^^^^^^
  File "/Users/amee/erpnext-bench/env/lib/python3.11/site-packages/redis/client.py", line 1266, in execute_command
    conn = self.connection or pool.get_connection(command_name, **options)
                              ^^^^^^^^^^^^^^^^^^^^^^^^^^^^^^^^^^^^^^^^^^^^
  File "/Users/amee/erpnext-bench/env/lib/python3.11/site-packages/redis/connection.py", line 1457, in get_connection
    connection.connect()
  File "/Users/amee/erpnext-bench/env/lib/python3.11/site-packages/redis/connection.py", line 705, in connect
    raise ConnectionError(self._error_message(e))
redis.exceptions.ConnectionError: Error 61 connecting to 127.0.0.1:11000. Connection refused.
2025-07-08 11:17:12,441 ERROR scheduler Exception in Enqueue Events for Site erp.amey.local
Traceback (most recent call last):
  File "/Users/amee/erpnext-bench/env/lib/python3.11/site-packages/redis/connection.py", line 699, in connect
    sock = self.retry.call_with_retry(
           ^^^^^^^^^^^^^^^^^^^^^^^^^^^
  File "/Users/amee/erpnext-bench/env/lib/python3.11/site-packages/redis/retry.py", line 46, in call_with_retry
    return do()
           ^^^^
  File "/Users/amee/erpnext-bench/env/lib/python3.11/site-packages/redis/connection.py", line 700, in <lambda>
    lambda: self._connect(), lambda error: self.disconnect(error)
            ^^^^^^^^^^^^^^^
  File "/Users/amee/erpnext-bench/env/lib/python3.11/site-packages/redis/connection.py", line 1002, in _connect
    raise err
  File "/Users/amee/erpnext-bench/env/lib/python3.11/site-packages/redis/connection.py", line 990, in _connect
    sock.connect(socket_address)
ConnectionRefusedError: [Errno 61] Connection refused

During handling of the above exception, another exception occurred:

Traceback (most recent call last):
  File "/Users/amee/erpnext-bench/apps/frappe/frappe/utils/scheduler.py", line 102, in enqueue_events_for_site
    enqueue_events(site=site)
  File "/Users/amee/erpnext-bench/apps/frappe/frappe/utils/scheduler.py", line 122, in enqueue_events
    if job_type.enqueue():
       ^^^^^^^^^^^^^^^^^^
  File "/Users/amee/erpnext-bench/apps/frappe/frappe/core/doctype/scheduled_job_type/scheduled_job_type.py", line 74, in enqueue
    if not self.is_job_in_queue():
           ^^^^^^^^^^^^^^^^^^^^^^
  File "/Users/amee/erpnext-bench/apps/frappe/frappe/core/doctype/scheduled_job_type/scheduled_job_type.py", line 95, in is_job_in_queue
    return is_job_enqueued(self.rq_job_id)
           ^^^^^^^^^^^^^^^^^^^^^^^^^^^^^^^
  File "/Users/amee/erpnext-bench/apps/frappe/frappe/utils/background_jobs.py", line 568, in is_job_enqueued
    return get_job_status(job_id) in (JobStatus.QUEUED, JobStatus.STARTED)
           ^^^^^^^^^^^^^^^^^^^^^^
  File "/Users/amee/erpnext-bench/apps/frappe/frappe/utils/background_jobs.py", line 573, in get_job_status
    job = get_job(job_id)
          ^^^^^^^^^^^^^^^
  File "/Users/amee/erpnext-bench/apps/frappe/frappe/utils/background_jobs.py", line 580, in get_job
    return Job.fetch(create_job_id(job_id), connection=get_redis_conn())
           ^^^^^^^^^^^^^^^^^^^^^^^^^^^^^^^^^^^^^^^^^^^^^^^^^^^^^^^^^^^^^
  File "/Users/amee/erpnext-bench/env/lib/python3.11/site-packages/rq/job.py", line 591, in fetch
    job.refresh()
  File "/Users/amee/erpnext-bench/env/lib/python3.11/site-packages/rq/job.py", line 989, in refresh
    data = self.connection.hgetall(self.key)
           ^^^^^^^^^^^^^^^^^^^^^^^^^^^^^^^^^
  File "/Users/amee/erpnext-bench/env/lib/python3.11/site-packages/redis/commands/core.py", line 4887, in hgetall
    return self.execute_command("HGETALL", name)
           ^^^^^^^^^^^^^^^^^^^^^^^^^^^^^^^^^^^^^
  File "/Users/amee/erpnext-bench/env/lib/python3.11/site-packages/redis/client.py", line 1266, in execute_command
    conn = self.connection or pool.get_connection(command_name, **options)
                              ^^^^^^^^^^^^^^^^^^^^^^^^^^^^^^^^^^^^^^^^^^^^
  File "/Users/amee/erpnext-bench/env/lib/python3.11/site-packages/redis/connection.py", line 1457, in get_connection
    connection.connect()
  File "/Users/amee/erpnext-bench/env/lib/python3.11/site-packages/redis/connection.py", line 705, in connect
    raise ConnectionError(self._error_message(e))
redis.exceptions.ConnectionError: Error 61 connecting to 127.0.0.1:11000. Connection refused.
2025-07-08 11:18:12,663 ERROR scheduler Exception in Enqueue Events for Site erp.amey.local
Traceback (most recent call last):
  File "/Users/amee/erpnext-bench/env/lib/python3.11/site-packages/redis/connection.py", line 699, in connect
    sock = self.retry.call_with_retry(
           ^^^^^^^^^^^^^^^^^^^^^^^^^^^
  File "/Users/amee/erpnext-bench/env/lib/python3.11/site-packages/redis/retry.py", line 46, in call_with_retry
    return do()
           ^^^^
  File "/Users/amee/erpnext-bench/env/lib/python3.11/site-packages/redis/connection.py", line 700, in <lambda>
    lambda: self._connect(), lambda error: self.disconnect(error)
            ^^^^^^^^^^^^^^^
  File "/Users/amee/erpnext-bench/env/lib/python3.11/site-packages/redis/connection.py", line 1002, in _connect
    raise err
  File "/Users/amee/erpnext-bench/env/lib/python3.11/site-packages/redis/connection.py", line 990, in _connect
    sock.connect(socket_address)
ConnectionRefusedError: [Errno 61] Connection refused

During handling of the above exception, another exception occurred:

Traceback (most recent call last):
  File "/Users/amee/erpnext-bench/apps/frappe/frappe/utils/scheduler.py", line 102, in enqueue_events_for_site
    enqueue_events(site=site)
  File "/Users/amee/erpnext-bench/apps/frappe/frappe/utils/scheduler.py", line 122, in enqueue_events
    if job_type.enqueue():
       ^^^^^^^^^^^^^^^^^^
  File "/Users/amee/erpnext-bench/apps/frappe/frappe/core/doctype/scheduled_job_type/scheduled_job_type.py", line 74, in enqueue
    if not self.is_job_in_queue():
           ^^^^^^^^^^^^^^^^^^^^^^
  File "/Users/amee/erpnext-bench/apps/frappe/frappe/core/doctype/scheduled_job_type/scheduled_job_type.py", line 95, in is_job_in_queue
    return is_job_enqueued(self.rq_job_id)
           ^^^^^^^^^^^^^^^^^^^^^^^^^^^^^^^
  File "/Users/amee/erpnext-bench/apps/frappe/frappe/utils/background_jobs.py", line 568, in is_job_enqueued
    return get_job_status(job_id) in (JobStatus.QUEUED, JobStatus.STARTED)
           ^^^^^^^^^^^^^^^^^^^^^^
  File "/Users/amee/erpnext-bench/apps/frappe/frappe/utils/background_jobs.py", line 573, in get_job_status
    job = get_job(job_id)
          ^^^^^^^^^^^^^^^
  File "/Users/amee/erpnext-bench/apps/frappe/frappe/utils/background_jobs.py", line 580, in get_job
    return Job.fetch(create_job_id(job_id), connection=get_redis_conn())
           ^^^^^^^^^^^^^^^^^^^^^^^^^^^^^^^^^^^^^^^^^^^^^^^^^^^^^^^^^^^^^
  File "/Users/amee/erpnext-bench/env/lib/python3.11/site-packages/rq/job.py", line 591, in fetch
    job.refresh()
  File "/Users/amee/erpnext-bench/env/lib/python3.11/site-packages/rq/job.py", line 989, in refresh
    data = self.connection.hgetall(self.key)
           ^^^^^^^^^^^^^^^^^^^^^^^^^^^^^^^^^
  File "/Users/amee/erpnext-bench/env/lib/python3.11/site-packages/redis/commands/core.py", line 4887, in hgetall
    return self.execute_command("HGETALL", name)
           ^^^^^^^^^^^^^^^^^^^^^^^^^^^^^^^^^^^^^
  File "/Users/amee/erpnext-bench/env/lib/python3.11/site-packages/redis/client.py", line 1266, in execute_command
    conn = self.connection or pool.get_connection(command_name, **options)
                              ^^^^^^^^^^^^^^^^^^^^^^^^^^^^^^^^^^^^^^^^^^^^
  File "/Users/amee/erpnext-bench/env/lib/python3.11/site-packages/redis/connection.py", line 1457, in get_connection
    connection.connect()
  File "/Users/amee/erpnext-bench/env/lib/python3.11/site-packages/redis/connection.py", line 705, in connect
    raise ConnectionError(self._error_message(e))
redis.exceptions.ConnectionError: Error 61 connecting to 127.0.0.1:11000. Connection refused.
2025-07-08 11:19:12,955 ERROR scheduler Exception in Enqueue Events for Site erp.amey.local
Traceback (most recent call last):
  File "/Users/amee/erpnext-bench/env/lib/python3.11/site-packages/redis/connection.py", line 699, in connect
    sock = self.retry.call_with_retry(
           ^^^^^^^^^^^^^^^^^^^^^^^^^^^
  File "/Users/amee/erpnext-bench/env/lib/python3.11/site-packages/redis/retry.py", line 46, in call_with_retry
    return do()
           ^^^^
  File "/Users/amee/erpnext-bench/env/lib/python3.11/site-packages/redis/connection.py", line 700, in <lambda>
    lambda: self._connect(), lambda error: self.disconnect(error)
            ^^^^^^^^^^^^^^^
  File "/Users/amee/erpnext-bench/env/lib/python3.11/site-packages/redis/connection.py", line 1002, in _connect
    raise err
  File "/Users/amee/erpnext-bench/env/lib/python3.11/site-packages/redis/connection.py", line 990, in _connect
    sock.connect(socket_address)
ConnectionRefusedError: [Errno 61] Connection refused

During handling of the above exception, another exception occurred:

Traceback (most recent call last):
  File "/Users/amee/erpnext-bench/apps/frappe/frappe/utils/scheduler.py", line 102, in enqueue_events_for_site
    enqueue_events(site=site)
  File "/Users/amee/erpnext-bench/apps/frappe/frappe/utils/scheduler.py", line 122, in enqueue_events
    if job_type.enqueue():
       ^^^^^^^^^^^^^^^^^^
  File "/Users/amee/erpnext-bench/apps/frappe/frappe/core/doctype/scheduled_job_type/scheduled_job_type.py", line 74, in enqueue
    if not self.is_job_in_queue():
           ^^^^^^^^^^^^^^^^^^^^^^
  File "/Users/amee/erpnext-bench/apps/frappe/frappe/core/doctype/scheduled_job_type/scheduled_job_type.py", line 95, in is_job_in_queue
    return is_job_enqueued(self.rq_job_id)
           ^^^^^^^^^^^^^^^^^^^^^^^^^^^^^^^
  File "/Users/amee/erpnext-bench/apps/frappe/frappe/utils/background_jobs.py", line 568, in is_job_enqueued
    return get_job_status(job_id) in (JobStatus.QUEUED, JobStatus.STARTED)
           ^^^^^^^^^^^^^^^^^^^^^^
  File "/Users/amee/erpnext-bench/apps/frappe/frappe/utils/background_jobs.py", line 573, in get_job_status
    job = get_job(job_id)
          ^^^^^^^^^^^^^^^
  File "/Users/amee/erpnext-bench/apps/frappe/frappe/utils/background_jobs.py", line 580, in get_job
    return Job.fetch(create_job_id(job_id), connection=get_redis_conn())
           ^^^^^^^^^^^^^^^^^^^^^^^^^^^^^^^^^^^^^^^^^^^^^^^^^^^^^^^^^^^^^
  File "/Users/amee/erpnext-bench/env/lib/python3.11/site-packages/rq/job.py", line 591, in fetch
    job.refresh()
  File "/Users/amee/erpnext-bench/env/lib/python3.11/site-packages/rq/job.py", line 989, in refresh
    data = self.connection.hgetall(self.key)
           ^^^^^^^^^^^^^^^^^^^^^^^^^^^^^^^^^
  File "/Users/amee/erpnext-bench/env/lib/python3.11/site-packages/redis/commands/core.py", line 4887, in hgetall
    return self.execute_command("HGETALL", name)
           ^^^^^^^^^^^^^^^^^^^^^^^^^^^^^^^^^^^^^
  File "/Users/amee/erpnext-bench/env/lib/python3.11/site-packages/redis/client.py", line 1266, in execute_command
    conn = self.connection or pool.get_connection(command_name, **options)
                              ^^^^^^^^^^^^^^^^^^^^^^^^^^^^^^^^^^^^^^^^^^^^
  File "/Users/amee/erpnext-bench/env/lib/python3.11/site-packages/redis/connection.py", line 1457, in get_connection
    connection.connect()
  File "/Users/amee/erpnext-bench/env/lib/python3.11/site-packages/redis/connection.py", line 705, in connect
    raise ConnectionError(self._error_message(e))
redis.exceptions.ConnectionError: Error 61 connecting to 127.0.0.1:11000. Connection refused.
2025-07-08 11:20:13,182 ERROR scheduler Exception in Enqueue Events for Site erp.amey.local
Traceback (most recent call last):
  File "/Users/amee/erpnext-bench/env/lib/python3.11/site-packages/redis/connection.py", line 699, in connect
    sock = self.retry.call_with_retry(
           ^^^^^^^^^^^^^^^^^^^^^^^^^^^
  File "/Users/amee/erpnext-bench/env/lib/python3.11/site-packages/redis/retry.py", line 46, in call_with_retry
    return do()
           ^^^^
  File "/Users/amee/erpnext-bench/env/lib/python3.11/site-packages/redis/connection.py", line 700, in <lambda>
    lambda: self._connect(), lambda error: self.disconnect(error)
            ^^^^^^^^^^^^^^^
  File "/Users/amee/erpnext-bench/env/lib/python3.11/site-packages/redis/connection.py", line 1002, in _connect
    raise err
  File "/Users/amee/erpnext-bench/env/lib/python3.11/site-packages/redis/connection.py", line 990, in _connect
    sock.connect(socket_address)
ConnectionRefusedError: [Errno 61] Connection refused

During handling of the above exception, another exception occurred:

Traceback (most recent call last):
  File "/Users/amee/erpnext-bench/apps/frappe/frappe/utils/scheduler.py", line 102, in enqueue_events_for_site
    enqueue_events(site=site)
  File "/Users/amee/erpnext-bench/apps/frappe/frappe/utils/scheduler.py", line 122, in enqueue_events
    if job_type.enqueue():
       ^^^^^^^^^^^^^^^^^^
  File "/Users/amee/erpnext-bench/apps/frappe/frappe/core/doctype/scheduled_job_type/scheduled_job_type.py", line 74, in enqueue
    if not self.is_job_in_queue():
           ^^^^^^^^^^^^^^^^^^^^^^
  File "/Users/amee/erpnext-bench/apps/frappe/frappe/core/doctype/scheduled_job_type/scheduled_job_type.py", line 95, in is_job_in_queue
    return is_job_enqueued(self.rq_job_id)
           ^^^^^^^^^^^^^^^^^^^^^^^^^^^^^^^
  File "/Users/amee/erpnext-bench/apps/frappe/frappe/utils/background_jobs.py", line 568, in is_job_enqueued
    return get_job_status(job_id) in (JobStatus.QUEUED, JobStatus.STARTED)
           ^^^^^^^^^^^^^^^^^^^^^^
  File "/Users/amee/erpnext-bench/apps/frappe/frappe/utils/background_jobs.py", line 573, in get_job_status
    job = get_job(job_id)
          ^^^^^^^^^^^^^^^
  File "/Users/amee/erpnext-bench/apps/frappe/frappe/utils/background_jobs.py", line 580, in get_job
    return Job.fetch(create_job_id(job_id), connection=get_redis_conn())
           ^^^^^^^^^^^^^^^^^^^^^^^^^^^^^^^^^^^^^^^^^^^^^^^^^^^^^^^^^^^^^
  File "/Users/amee/erpnext-bench/env/lib/python3.11/site-packages/rq/job.py", line 591, in fetch
    job.refresh()
  File "/Users/amee/erpnext-bench/env/lib/python3.11/site-packages/rq/job.py", line 989, in refresh
    data = self.connection.hgetall(self.key)
           ^^^^^^^^^^^^^^^^^^^^^^^^^^^^^^^^^
  File "/Users/amee/erpnext-bench/env/lib/python3.11/site-packages/redis/commands/core.py", line 4887, in hgetall
    return self.execute_command("HGETALL", name)
           ^^^^^^^^^^^^^^^^^^^^^^^^^^^^^^^^^^^^^
  File "/Users/amee/erpnext-bench/env/lib/python3.11/site-packages/redis/client.py", line 1266, in execute_command
    conn = self.connection or pool.get_connection(command_name, **options)
                              ^^^^^^^^^^^^^^^^^^^^^^^^^^^^^^^^^^^^^^^^^^^^
  File "/Users/amee/erpnext-bench/env/lib/python3.11/site-packages/redis/connection.py", line 1457, in get_connection
    connection.connect()
  File "/Users/amee/erpnext-bench/env/lib/python3.11/site-packages/redis/connection.py", line 705, in connect
    raise ConnectionError(self._error_message(e))
redis.exceptions.ConnectionError: Error 61 connecting to 127.0.0.1:11000. Connection refused.
2025-07-08 11:21:13,392 ERROR scheduler Exception in Enqueue Events for Site erp.amey.local
Traceback (most recent call last):
  File "/Users/amee/erpnext-bench/env/lib/python3.11/site-packages/redis/connection.py", line 699, in connect
    sock = self.retry.call_with_retry(
           ^^^^^^^^^^^^^^^^^^^^^^^^^^^
  File "/Users/amee/erpnext-bench/env/lib/python3.11/site-packages/redis/retry.py", line 46, in call_with_retry
    return do()
           ^^^^
  File "/Users/amee/erpnext-bench/env/lib/python3.11/site-packages/redis/connection.py", line 700, in <lambda>
    lambda: self._connect(), lambda error: self.disconnect(error)
            ^^^^^^^^^^^^^^^
  File "/Users/amee/erpnext-bench/env/lib/python3.11/site-packages/redis/connection.py", line 1002, in _connect
    raise err
  File "/Users/amee/erpnext-bench/env/lib/python3.11/site-packages/redis/connection.py", line 990, in _connect
    sock.connect(socket_address)
ConnectionRefusedError: [Errno 61] Connection refused

During handling of the above exception, another exception occurred:

Traceback (most recent call last):
  File "/Users/amee/erpnext-bench/apps/frappe/frappe/utils/scheduler.py", line 102, in enqueue_events_for_site
    enqueue_events(site=site)
  File "/Users/amee/erpnext-bench/apps/frappe/frappe/utils/scheduler.py", line 122, in enqueue_events
    if job_type.enqueue():
       ^^^^^^^^^^^^^^^^^^
  File "/Users/amee/erpnext-bench/apps/frappe/frappe/core/doctype/scheduled_job_type/scheduled_job_type.py", line 74, in enqueue
    if not self.is_job_in_queue():
           ^^^^^^^^^^^^^^^^^^^^^^
  File "/Users/amee/erpnext-bench/apps/frappe/frappe/core/doctype/scheduled_job_type/scheduled_job_type.py", line 95, in is_job_in_queue
    return is_job_enqueued(self.rq_job_id)
           ^^^^^^^^^^^^^^^^^^^^^^^^^^^^^^^
  File "/Users/amee/erpnext-bench/apps/frappe/frappe/utils/background_jobs.py", line 568, in is_job_enqueued
    return get_job_status(job_id) in (JobStatus.QUEUED, JobStatus.STARTED)
           ^^^^^^^^^^^^^^^^^^^^^^
  File "/Users/amee/erpnext-bench/apps/frappe/frappe/utils/background_jobs.py", line 573, in get_job_status
    job = get_job(job_id)
          ^^^^^^^^^^^^^^^
  File "/Users/amee/erpnext-bench/apps/frappe/frappe/utils/background_jobs.py", line 580, in get_job
    return Job.fetch(create_job_id(job_id), connection=get_redis_conn())
           ^^^^^^^^^^^^^^^^^^^^^^^^^^^^^^^^^^^^^^^^^^^^^^^^^^^^^^^^^^^^^
  File "/Users/amee/erpnext-bench/env/lib/python3.11/site-packages/rq/job.py", line 591, in fetch
    job.refresh()
  File "/Users/amee/erpnext-bench/env/lib/python3.11/site-packages/rq/job.py", line 989, in refresh
    data = self.connection.hgetall(self.key)
           ^^^^^^^^^^^^^^^^^^^^^^^^^^^^^^^^^
  File "/Users/amee/erpnext-bench/env/lib/python3.11/site-packages/redis/commands/core.py", line 4887, in hgetall
    return self.execute_command("HGETALL", name)
           ^^^^^^^^^^^^^^^^^^^^^^^^^^^^^^^^^^^^^
  File "/Users/amee/erpnext-bench/env/lib/python3.11/site-packages/redis/client.py", line 1266, in execute_command
    conn = self.connection or pool.get_connection(command_name, **options)
                              ^^^^^^^^^^^^^^^^^^^^^^^^^^^^^^^^^^^^^^^^^^^^
  File "/Users/amee/erpnext-bench/env/lib/python3.11/site-packages/redis/connection.py", line 1457, in get_connection
    connection.connect()
  File "/Users/amee/erpnext-bench/env/lib/python3.11/site-packages/redis/connection.py", line 705, in connect
    raise ConnectionError(self._error_message(e))
redis.exceptions.ConnectionError: Error 61 connecting to 127.0.0.1:11000. Connection refused.
2025-07-08 11:22:13,584 ERROR scheduler Exception in Enqueue Events for Site erp.amey.local
Traceback (most recent call last):
  File "/Users/amee/erpnext-bench/env/lib/python3.11/site-packages/redis/connection.py", line 699, in connect
    sock = self.retry.call_with_retry(
           ^^^^^^^^^^^^^^^^^^^^^^^^^^^
  File "/Users/amee/erpnext-bench/env/lib/python3.11/site-packages/redis/retry.py", line 46, in call_with_retry
    return do()
           ^^^^
  File "/Users/amee/erpnext-bench/env/lib/python3.11/site-packages/redis/connection.py", line 700, in <lambda>
    lambda: self._connect(), lambda error: self.disconnect(error)
            ^^^^^^^^^^^^^^^
  File "/Users/amee/erpnext-bench/env/lib/python3.11/site-packages/redis/connection.py", line 1002, in _connect
    raise err
  File "/Users/amee/erpnext-bench/env/lib/python3.11/site-packages/redis/connection.py", line 990, in _connect
    sock.connect(socket_address)
ConnectionRefusedError: [Errno 61] Connection refused

During handling of the above exception, another exception occurred:

Traceback (most recent call last):
  File "/Users/amee/erpnext-bench/apps/frappe/frappe/utils/scheduler.py", line 102, in enqueue_events_for_site
    enqueue_events(site=site)
  File "/Users/amee/erpnext-bench/apps/frappe/frappe/utils/scheduler.py", line 122, in enqueue_events
    if job_type.enqueue():
       ^^^^^^^^^^^^^^^^^^
  File "/Users/amee/erpnext-bench/apps/frappe/frappe/core/doctype/scheduled_job_type/scheduled_job_type.py", line 74, in enqueue
    if not self.is_job_in_queue():
           ^^^^^^^^^^^^^^^^^^^^^^
  File "/Users/amee/erpnext-bench/apps/frappe/frappe/core/doctype/scheduled_job_type/scheduled_job_type.py", line 95, in is_job_in_queue
    return is_job_enqueued(self.rq_job_id)
           ^^^^^^^^^^^^^^^^^^^^^^^^^^^^^^^
  File "/Users/amee/erpnext-bench/apps/frappe/frappe/utils/background_jobs.py", line 568, in is_job_enqueued
    return get_job_status(job_id) in (JobStatus.QUEUED, JobStatus.STARTED)
           ^^^^^^^^^^^^^^^^^^^^^^
  File "/Users/amee/erpnext-bench/apps/frappe/frappe/utils/background_jobs.py", line 573, in get_job_status
    job = get_job(job_id)
          ^^^^^^^^^^^^^^^
  File "/Users/amee/erpnext-bench/apps/frappe/frappe/utils/background_jobs.py", line 580, in get_job
    return Job.fetch(create_job_id(job_id), connection=get_redis_conn())
           ^^^^^^^^^^^^^^^^^^^^^^^^^^^^^^^^^^^^^^^^^^^^^^^^^^^^^^^^^^^^^
  File "/Users/amee/erpnext-bench/env/lib/python3.11/site-packages/rq/job.py", line 591, in fetch
    job.refresh()
  File "/Users/amee/erpnext-bench/env/lib/python3.11/site-packages/rq/job.py", line 989, in refresh
    data = self.connection.hgetall(self.key)
           ^^^^^^^^^^^^^^^^^^^^^^^^^^^^^^^^^
  File "/Users/amee/erpnext-bench/env/lib/python3.11/site-packages/redis/commands/core.py", line 4887, in hgetall
    return self.execute_command("HGETALL", name)
           ^^^^^^^^^^^^^^^^^^^^^^^^^^^^^^^^^^^^^
  File "/Users/amee/erpnext-bench/env/lib/python3.11/site-packages/redis/client.py", line 1266, in execute_command
    conn = self.connection or pool.get_connection(command_name, **options)
                              ^^^^^^^^^^^^^^^^^^^^^^^^^^^^^^^^^^^^^^^^^^^^
  File "/Users/amee/erpnext-bench/env/lib/python3.11/site-packages/redis/connection.py", line 1457, in get_connection
    connection.connect()
  File "/Users/amee/erpnext-bench/env/lib/python3.11/site-packages/redis/connection.py", line 705, in connect
    raise ConnectionError(self._error_message(e))
redis.exceptions.ConnectionError: Error 61 connecting to 127.0.0.1:11000. Connection refused.
2025-07-08 11:23:13,782 ERROR scheduler Exception in Enqueue Events for Site erp.amey.local
Traceback (most recent call last):
  File "/Users/amee/erpnext-bench/env/lib/python3.11/site-packages/redis/connection.py", line 699, in connect
    sock = self.retry.call_with_retry(
           ^^^^^^^^^^^^^^^^^^^^^^^^^^^
  File "/Users/amee/erpnext-bench/env/lib/python3.11/site-packages/redis/retry.py", line 46, in call_with_retry
    return do()
           ^^^^
  File "/Users/amee/erpnext-bench/env/lib/python3.11/site-packages/redis/connection.py", line 700, in <lambda>
    lambda: self._connect(), lambda error: self.disconnect(error)
            ^^^^^^^^^^^^^^^
  File "/Users/amee/erpnext-bench/env/lib/python3.11/site-packages/redis/connection.py", line 1002, in _connect
    raise err
  File "/Users/amee/erpnext-bench/env/lib/python3.11/site-packages/redis/connection.py", line 990, in _connect
    sock.connect(socket_address)
ConnectionRefusedError: [Errno 61] Connection refused

During handling of the above exception, another exception occurred:

Traceback (most recent call last):
  File "/Users/amee/erpnext-bench/apps/frappe/frappe/utils/scheduler.py", line 102, in enqueue_events_for_site
    enqueue_events(site=site)
  File "/Users/amee/erpnext-bench/apps/frappe/frappe/utils/scheduler.py", line 122, in enqueue_events
    if job_type.enqueue():
       ^^^^^^^^^^^^^^^^^^
  File "/Users/amee/erpnext-bench/apps/frappe/frappe/core/doctype/scheduled_job_type/scheduled_job_type.py", line 74, in enqueue
    if not self.is_job_in_queue():
           ^^^^^^^^^^^^^^^^^^^^^^
  File "/Users/amee/erpnext-bench/apps/frappe/frappe/core/doctype/scheduled_job_type/scheduled_job_type.py", line 95, in is_job_in_queue
    return is_job_enqueued(self.rq_job_id)
           ^^^^^^^^^^^^^^^^^^^^^^^^^^^^^^^
  File "/Users/amee/erpnext-bench/apps/frappe/frappe/utils/background_jobs.py", line 568, in is_job_enqueued
    return get_job_status(job_id) in (JobStatus.QUEUED, JobStatus.STARTED)
           ^^^^^^^^^^^^^^^^^^^^^^
  File "/Users/amee/erpnext-bench/apps/frappe/frappe/utils/background_jobs.py", line 573, in get_job_status
    job = get_job(job_id)
          ^^^^^^^^^^^^^^^
  File "/Users/amee/erpnext-bench/apps/frappe/frappe/utils/background_jobs.py", line 580, in get_job
    return Job.fetch(create_job_id(job_id), connection=get_redis_conn())
           ^^^^^^^^^^^^^^^^^^^^^^^^^^^^^^^^^^^^^^^^^^^^^^^^^^^^^^^^^^^^^
  File "/Users/amee/erpnext-bench/env/lib/python3.11/site-packages/rq/job.py", line 591, in fetch
    job.refresh()
  File "/Users/amee/erpnext-bench/env/lib/python3.11/site-packages/rq/job.py", line 989, in refresh
    data = self.connection.hgetall(self.key)
           ^^^^^^^^^^^^^^^^^^^^^^^^^^^^^^^^^
  File "/Users/amee/erpnext-bench/env/lib/python3.11/site-packages/redis/commands/core.py", line 4887, in hgetall
    return self.execute_command("HGETALL", name)
           ^^^^^^^^^^^^^^^^^^^^^^^^^^^^^^^^^^^^^
  File "/Users/amee/erpnext-bench/env/lib/python3.11/site-packages/redis/client.py", line 1266, in execute_command
    conn = self.connection or pool.get_connection(command_name, **options)
                              ^^^^^^^^^^^^^^^^^^^^^^^^^^^^^^^^^^^^^^^^^^^^
  File "/Users/amee/erpnext-bench/env/lib/python3.11/site-packages/redis/connection.py", line 1457, in get_connection
    connection.connect()
  File "/Users/amee/erpnext-bench/env/lib/python3.11/site-packages/redis/connection.py", line 705, in connect
    raise ConnectionError(self._error_message(e))
redis.exceptions.ConnectionError: Error 61 connecting to 127.0.0.1:11000. Connection refused.
2025-07-08 11:24:13,973 ERROR scheduler Exception in Enqueue Events for Site erp.amey.local
Traceback (most recent call last):
  File "/Users/amee/erpnext-bench/env/lib/python3.11/site-packages/redis/connection.py", line 699, in connect
    sock = self.retry.call_with_retry(
           ^^^^^^^^^^^^^^^^^^^^^^^^^^^
  File "/Users/amee/erpnext-bench/env/lib/python3.11/site-packages/redis/retry.py", line 46, in call_with_retry
    return do()
           ^^^^
  File "/Users/amee/erpnext-bench/env/lib/python3.11/site-packages/redis/connection.py", line 700, in <lambda>
    lambda: self._connect(), lambda error: self.disconnect(error)
            ^^^^^^^^^^^^^^^
  File "/Users/amee/erpnext-bench/env/lib/python3.11/site-packages/redis/connection.py", line 1002, in _connect
    raise err
  File "/Users/amee/erpnext-bench/env/lib/python3.11/site-packages/redis/connection.py", line 990, in _connect
    sock.connect(socket_address)
ConnectionRefusedError: [Errno 61] Connection refused

During handling of the above exception, another exception occurred:

Traceback (most recent call last):
  File "/Users/amee/erpnext-bench/apps/frappe/frappe/utils/scheduler.py", line 102, in enqueue_events_for_site
    enqueue_events(site=site)
  File "/Users/amee/erpnext-bench/apps/frappe/frappe/utils/scheduler.py", line 122, in enqueue_events
    if job_type.enqueue():
       ^^^^^^^^^^^^^^^^^^
  File "/Users/amee/erpnext-bench/apps/frappe/frappe/core/doctype/scheduled_job_type/scheduled_job_type.py", line 74, in enqueue
    if not self.is_job_in_queue():
           ^^^^^^^^^^^^^^^^^^^^^^
  File "/Users/amee/erpnext-bench/apps/frappe/frappe/core/doctype/scheduled_job_type/scheduled_job_type.py", line 95, in is_job_in_queue
    return is_job_enqueued(self.rq_job_id)
           ^^^^^^^^^^^^^^^^^^^^^^^^^^^^^^^
  File "/Users/amee/erpnext-bench/apps/frappe/frappe/utils/background_jobs.py", line 568, in is_job_enqueued
    return get_job_status(job_id) in (JobStatus.QUEUED, JobStatus.STARTED)
           ^^^^^^^^^^^^^^^^^^^^^^
  File "/Users/amee/erpnext-bench/apps/frappe/frappe/utils/background_jobs.py", line 573, in get_job_status
    job = get_job(job_id)
          ^^^^^^^^^^^^^^^
  File "/Users/amee/erpnext-bench/apps/frappe/frappe/utils/background_jobs.py", line 580, in get_job
    return Job.fetch(create_job_id(job_id), connection=get_redis_conn())
           ^^^^^^^^^^^^^^^^^^^^^^^^^^^^^^^^^^^^^^^^^^^^^^^^^^^^^^^^^^^^^
  File "/Users/amee/erpnext-bench/env/lib/python3.11/site-packages/rq/job.py", line 591, in fetch
    job.refresh()
  File "/Users/amee/erpnext-bench/env/lib/python3.11/site-packages/rq/job.py", line 989, in refresh
    data = self.connection.hgetall(self.key)
           ^^^^^^^^^^^^^^^^^^^^^^^^^^^^^^^^^
  File "/Users/amee/erpnext-bench/env/lib/python3.11/site-packages/redis/commands/core.py", line 4887, in hgetall
    return self.execute_command("HGETALL", name)
           ^^^^^^^^^^^^^^^^^^^^^^^^^^^^^^^^^^^^^
  File "/Users/amee/erpnext-bench/env/lib/python3.11/site-packages/redis/client.py", line 1266, in execute_command
    conn = self.connection or pool.get_connection(command_name, **options)
                              ^^^^^^^^^^^^^^^^^^^^^^^^^^^^^^^^^^^^^^^^^^^^
  File "/Users/amee/erpnext-bench/env/lib/python3.11/site-packages/redis/connection.py", line 1457, in get_connection
    connection.connect()
  File "/Users/amee/erpnext-bench/env/lib/python3.11/site-packages/redis/connection.py", line 705, in connect
    raise ConnectionError(self._error_message(e))
redis.exceptions.ConnectionError: Error 61 connecting to 127.0.0.1:11000. Connection refused.
2025-07-08 11:25:14,170 ERROR scheduler Exception in Enqueue Events for Site erp.amey.local
Traceback (most recent call last):
  File "/Users/amee/erpnext-bench/env/lib/python3.11/site-packages/redis/connection.py", line 699, in connect
    sock = self.retry.call_with_retry(
           ^^^^^^^^^^^^^^^^^^^^^^^^^^^
  File "/Users/amee/erpnext-bench/env/lib/python3.11/site-packages/redis/retry.py", line 46, in call_with_retry
    return do()
           ^^^^
  File "/Users/amee/erpnext-bench/env/lib/python3.11/site-packages/redis/connection.py", line 700, in <lambda>
    lambda: self._connect(), lambda error: self.disconnect(error)
            ^^^^^^^^^^^^^^^
  File "/Users/amee/erpnext-bench/env/lib/python3.11/site-packages/redis/connection.py", line 1002, in _connect
    raise err
  File "/Users/amee/erpnext-bench/env/lib/python3.11/site-packages/redis/connection.py", line 990, in _connect
    sock.connect(socket_address)
ConnectionRefusedError: [Errno 61] Connection refused

During handling of the above exception, another exception occurred:

Traceback (most recent call last):
  File "/Users/amee/erpnext-bench/apps/frappe/frappe/utils/scheduler.py", line 102, in enqueue_events_for_site
    enqueue_events(site=site)
  File "/Users/amee/erpnext-bench/apps/frappe/frappe/utils/scheduler.py", line 122, in enqueue_events
    if job_type.enqueue():
       ^^^^^^^^^^^^^^^^^^
  File "/Users/amee/erpnext-bench/apps/frappe/frappe/core/doctype/scheduled_job_type/scheduled_job_type.py", line 74, in enqueue
    if not self.is_job_in_queue():
           ^^^^^^^^^^^^^^^^^^^^^^
  File "/Users/amee/erpnext-bench/apps/frappe/frappe/core/doctype/scheduled_job_type/scheduled_job_type.py", line 95, in is_job_in_queue
    return is_job_enqueued(self.rq_job_id)
           ^^^^^^^^^^^^^^^^^^^^^^^^^^^^^^^
  File "/Users/amee/erpnext-bench/apps/frappe/frappe/utils/background_jobs.py", line 568, in is_job_enqueued
    return get_job_status(job_id) in (JobStatus.QUEUED, JobStatus.STARTED)
           ^^^^^^^^^^^^^^^^^^^^^^
  File "/Users/amee/erpnext-bench/apps/frappe/frappe/utils/background_jobs.py", line 573, in get_job_status
    job = get_job(job_id)
          ^^^^^^^^^^^^^^^
  File "/Users/amee/erpnext-bench/apps/frappe/frappe/utils/background_jobs.py", line 580, in get_job
    return Job.fetch(create_job_id(job_id), connection=get_redis_conn())
           ^^^^^^^^^^^^^^^^^^^^^^^^^^^^^^^^^^^^^^^^^^^^^^^^^^^^^^^^^^^^^
  File "/Users/amee/erpnext-bench/env/lib/python3.11/site-packages/rq/job.py", line 591, in fetch
    job.refresh()
  File "/Users/amee/erpnext-bench/env/lib/python3.11/site-packages/rq/job.py", line 989, in refresh
    data = self.connection.hgetall(self.key)
           ^^^^^^^^^^^^^^^^^^^^^^^^^^^^^^^^^
  File "/Users/amee/erpnext-bench/env/lib/python3.11/site-packages/redis/commands/core.py", line 4887, in hgetall
    return self.execute_command("HGETALL", name)
           ^^^^^^^^^^^^^^^^^^^^^^^^^^^^^^^^^^^^^
  File "/Users/amee/erpnext-bench/env/lib/python3.11/site-packages/redis/client.py", line 1266, in execute_command
    conn = self.connection or pool.get_connection(command_name, **options)
                              ^^^^^^^^^^^^^^^^^^^^^^^^^^^^^^^^^^^^^^^^^^^^
  File "/Users/amee/erpnext-bench/env/lib/python3.11/site-packages/redis/connection.py", line 1457, in get_connection
    connection.connect()
  File "/Users/amee/erpnext-bench/env/lib/python3.11/site-packages/redis/connection.py", line 705, in connect
    raise ConnectionError(self._error_message(e))
redis.exceptions.ConnectionError: Error 61 connecting to 127.0.0.1:11000. Connection refused.
2025-07-11 10:46:03,367 ERROR scheduler Skipped queueing frappe.automation.doctype.auto_repeat.auto_repeat.make_auto_repeat_entry because it was found in queue for erp.amey.local
2025-07-11 16:01:39,731 ERROR scheduler Skipped queueing frappe.website.doctype.web_page.web_page.check_publish_status because it was found in queue for erp.amey.local
2025-07-11 16:01:39,890 ERROR scheduler Skipped queueing erpnext.stock.doctype.repost_item_valuation.repost_item_valuation.repost_entries because it was found in queue for erp.amey.local
2025-07-11 16:01:39,953 ERROR scheduler Skipped queueing frappe.desk.page.backups.backups.delete_downloadable_backups because it was found in queue for erp.amey.local
2025-07-11 16:01:39,960 ERROR scheduler Skipped queueing erpnext.utilities.bulk_transaction.retry because it was found in queue for erp.amey.local
2025-07-11 16:01:39,970 ERROR scheduler Skipped queueing frappe.twofactor.delete_all_barcodes_for_users because it was found in queue for erp.amey.local
2025-07-11 16:01:40,053 ERROR scheduler Skipped queueing frappe.model.utils.user_settings.sync_user_settings because it was found in queue for erp.amey.local
2025-07-11 16:01:40,079 ERROR scheduler Skipped queueing frappe.website.doctype.personal_data_deletion_request.personal_data_deletion_request.process_data_deletion_request because it was found in queue for erp.amey.local
2025-07-11 16:01:40,139 ERROR scheduler Skipped queueing frappe.email.doctype.newsletter.newsletter.send_scheduled_email because it was found in queue for erp.amey.local
2025-07-11 16:01:40,148 ERROR scheduler Skipped queueing frappe.core.doctype.prepared_report.prepared_report.expire_stalled_report because it was found in queue for erp.amey.local
2025-07-11 16:01:40,208 ERROR scheduler Skipped queueing frappe.desk.form.document_follow.send_hourly_updates because it was found in queue for erp.amey.local
2025-07-11 16:01:40,340 ERROR scheduler Skipped queueing frappe.oauth.delete_oauth2_data because it was found in queue for erp.amey.local
2025-07-15 16:18:20,125 ERROR scheduler Exception in Enqueue Events for Site erp.amey.local
Traceback (most recent call last):
  File "/Users/amee/erpnext-bench/env/lib/python3.11/site-packages/pymysql/connections.py", line 649, in connect
    sock = socket.create_connection(
           ^^^^^^^^^^^^^^^^^^^^^^^^^
  File "/Users/amee/.pyenv/versions/3.11.9/lib/python3.11/socket.py", line 851, in create_connection
    raise exceptions[0]
  File "/Users/amee/.pyenv/versions/3.11.9/lib/python3.11/socket.py", line 836, in create_connection
    sock.connect(sa)
ConnectionRefusedError: [Errno 61] Connection refused

During handling of the above exception, another exception occurred:

Traceback (most recent call last):
  File "/Users/amee/erpnext-bench/apps/frappe/frappe/utils/scheduler.py", line 99, in enqueue_events_for_site
    if is_scheduler_inactive():
       ^^^^^^^^^^^^^^^^^^^^^^^
  File "/Users/amee/erpnext-bench/apps/frappe/frappe/utils/scheduler.py", line 143, in is_scheduler_inactive
    if is_scheduler_disabled(verbose=verbose):
       ^^^^^^^^^^^^^^^^^^^^^^^^^^^^^^^^^^^^^^
  File "/Users/amee/erpnext-bench/apps/frappe/frappe/utils/scheduler.py", line 156, in is_scheduler_disabled
    frappe.db.get_single_value("System Settings", "enable_scheduler")
  File "/Users/amee/erpnext-bench/apps/frappe/frappe/database/database.py", line 837, in get_single_value
    ).run()
      ^^^^^
  File "/Users/amee/erpnext-bench/apps/frappe/frappe/query_builder/utils.py", line 87, in execute_query
    result = frappe.db.sql(query, params, *args, **kwargs)  # nosemgrep
             ^^^^^^^^^^^^^^^^^^^^^^^^^^^^^^^^^^^^^^^^^^^^^
  File "/Users/amee/erpnext-bench/apps/frappe/frappe/database/database.py", line 207, in sql
    self.connect()
  File "/Users/amee/erpnext-bench/apps/frappe/frappe/database/database.py", line 112, in connect
    self._conn: "MariadbConnection" | "PostgresConnection" = self.get_connection()
                                                             ^^^^^^^^^^^^^^^^^^^^^
  File "/Users/amee/erpnext-bench/apps/frappe/frappe/database/mariadb/database.py", line 108, in get_connection
    conn = self._get_connection()
           ^^^^^^^^^^^^^^^^^^^^^^
  File "/Users/amee/erpnext-bench/apps/frappe/frappe/database/mariadb/database.py", line 114, in _get_connection
    return self.create_connection()
           ^^^^^^^^^^^^^^^^^^^^^^^^
  File "/Users/amee/erpnext-bench/apps/frappe/frappe/database/mariadb/database.py", line 117, in create_connection
    return pymysql.connect(**self.get_connection_settings())
           ^^^^^^^^^^^^^^^^^^^^^^^^^^^^^^^^^^^^^^^^^^^^^^^^^
  File "/Users/amee/erpnext-bench/env/lib/python3.11/site-packages/pymysql/connections.py", line 361, in __init__
    self.connect()
  File "/Users/amee/erpnext-bench/env/lib/python3.11/site-packages/pymysql/connections.py", line 716, in connect
    raise exc
pymysql.err.OperationalError: (2003, "Can't connect to MySQL server on '127.0.0.1' ([Errno 61] Connection refused)")
2025-07-15 16:27:23,144 ERROR scheduler Exception in Enqueue Events for Site erp.amey.local
Traceback (most recent call last):
  File "/Users/amee/erpnext-bench/apps/frappe/frappe/utils/scheduler.py", line 99, in enqueue_events_for_site
    if is_scheduler_inactive():
       ^^^^^^^^^^^^^^^^^^^^^^^
  File "/Users/amee/erpnext-bench/apps/frappe/frappe/utils/scheduler.py", line 143, in is_scheduler_inactive
    if is_scheduler_disabled(verbose=verbose):
       ^^^^^^^^^^^^^^^^^^^^^^^^^^^^^^^^^^^^^^
  File "/Users/amee/erpnext-bench/apps/frappe/frappe/utils/scheduler.py", line 156, in is_scheduler_disabled
    frappe.db.get_single_value("System Settings", "enable_scheduler")
  File "/Users/amee/erpnext-bench/apps/frappe/frappe/database/database.py", line 837, in get_single_value
    ).run()
      ^^^^^
  File "/Users/amee/erpnext-bench/apps/frappe/frappe/query_builder/utils.py", line 87, in execute_query
    result = frappe.db.sql(query, params, *args, **kwargs)  # nosemgrep
             ^^^^^^^^^^^^^^^^^^^^^^^^^^^^^^^^^^^^^^^^^^^^^
  File "/Users/amee/erpnext-bench/apps/frappe/frappe/database/database.py", line 207, in sql
    self.connect()
  File "/Users/amee/erpnext-bench/apps/frappe/frappe/database/database.py", line 112, in connect
    self._conn: "MariadbConnection" | "PostgresConnection" = self.get_connection()
                                                             ^^^^^^^^^^^^^^^^^^^^^
  File "/Users/amee/erpnext-bench/apps/frappe/frappe/database/mariadb/database.py", line 108, in get_connection
    conn = self._get_connection()
           ^^^^^^^^^^^^^^^^^^^^^^
  File "/Users/amee/erpnext-bench/apps/frappe/frappe/database/mariadb/database.py", line 114, in _get_connection
    return self.create_connection()
           ^^^^^^^^^^^^^^^^^^^^^^^^
  File "/Users/amee/erpnext-bench/apps/frappe/frappe/database/mariadb/database.py", line 117, in create_connection
    return pymysql.connect(**self.get_connection_settings())
           ^^^^^^^^^^^^^^^^^^^^^^^^^^^^^^^^^^^^^^^^^^^^^^^^^
  File "/Users/amee/erpnext-bench/env/lib/python3.11/site-packages/pymysql/connections.py", line 361, in __init__
    self.connect()
  File "/Users/amee/erpnext-bench/env/lib/python3.11/site-packages/pymysql/connections.py", line 668, in connect
    self._get_server_information()
  File "/Users/amee/erpnext-bench/env/lib/python3.11/site-packages/pymysql/connections.py", line 1098, in _get_server_information
    packet = self._read_packet()
             ^^^^^^^^^^^^^^^^^^^
  File "/Users/amee/erpnext-bench/env/lib/python3.11/site-packages/pymysql/connections.py", line 744, in _read_packet
    packet_header = self._read_bytes(4)
                    ^^^^^^^^^^^^^^^^^^^
  File "/Users/amee/erpnext-bench/env/lib/python3.11/site-packages/pymysql/connections.py", line 798, in _read_bytes
    raise err.OperationalError(
pymysql.err.OperationalError: (2013, 'Lost connection to MySQL server during query')
2025-07-15 16:28:23,446 ERROR scheduler Exception in Enqueue Events for Site erp.amey.local
Traceback (most recent call last):
  File "/Users/amee/erpnext-bench/apps/frappe/frappe/utils/scheduler.py", line 99, in enqueue_events_for_site
    if is_scheduler_inactive():
       ^^^^^^^^^^^^^^^^^^^^^^^
  File "/Users/amee/erpnext-bench/apps/frappe/frappe/utils/scheduler.py", line 143, in is_scheduler_inactive
    if is_scheduler_disabled(verbose=verbose):
       ^^^^^^^^^^^^^^^^^^^^^^^^^^^^^^^^^^^^^^
  File "/Users/amee/erpnext-bench/apps/frappe/frappe/utils/scheduler.py", line 156, in is_scheduler_disabled
    frappe.db.get_single_value("System Settings", "enable_scheduler")
  File "/Users/amee/erpnext-bench/apps/frappe/frappe/database/database.py", line 837, in get_single_value
    ).run()
      ^^^^^
  File "/Users/amee/erpnext-bench/apps/frappe/frappe/query_builder/utils.py", line 87, in execute_query
    result = frappe.db.sql(query, params, *args, **kwargs)  # nosemgrep
             ^^^^^^^^^^^^^^^^^^^^^^^^^^^^^^^^^^^^^^^^^^^^^
  File "/Users/amee/erpnext-bench/apps/frappe/frappe/database/database.py", line 207, in sql
    self.connect()
  File "/Users/amee/erpnext-bench/apps/frappe/frappe/database/database.py", line 112, in connect
    self._conn: "MariadbConnection" | "PostgresConnection" = self.get_connection()
                                                             ^^^^^^^^^^^^^^^^^^^^^
  File "/Users/amee/erpnext-bench/apps/frappe/frappe/database/mariadb/database.py", line 108, in get_connection
    conn = self._get_connection()
           ^^^^^^^^^^^^^^^^^^^^^^
  File "/Users/amee/erpnext-bench/apps/frappe/frappe/database/mariadb/database.py", line 114, in _get_connection
    return self.create_connection()
           ^^^^^^^^^^^^^^^^^^^^^^^^
  File "/Users/amee/erpnext-bench/apps/frappe/frappe/database/mariadb/database.py", line 117, in create_connection
    return pymysql.connect(**self.get_connection_settings())
           ^^^^^^^^^^^^^^^^^^^^^^^^^^^^^^^^^^^^^^^^^^^^^^^^^
  File "/Users/amee/erpnext-bench/env/lib/python3.11/site-packages/pymysql/connections.py", line 361, in __init__
    self.connect()
  File "/Users/amee/erpnext-bench/env/lib/python3.11/site-packages/pymysql/connections.py", line 668, in connect
    self._get_server_information()
  File "/Users/amee/erpnext-bench/env/lib/python3.11/site-packages/pymysql/connections.py", line 1098, in _get_server_information
    packet = self._read_packet()
             ^^^^^^^^^^^^^^^^^^^
  File "/Users/amee/erpnext-bench/env/lib/python3.11/site-packages/pymysql/connections.py", line 744, in _read_packet
    packet_header = self._read_bytes(4)
                    ^^^^^^^^^^^^^^^^^^^
  File "/Users/amee/erpnext-bench/env/lib/python3.11/site-packages/pymysql/connections.py", line 798, in _read_bytes
    raise err.OperationalError(
pymysql.err.OperationalError: (2013, 'Lost connection to MySQL server during query')
2025-07-15 16:29:23,819 ERROR scheduler Exception in Enqueue Events for Site erp.amey.local
Traceback (most recent call last):
  File "/Users/amee/erpnext-bench/apps/frappe/frappe/utils/scheduler.py", line 99, in enqueue_events_for_site
    if is_scheduler_inactive():
       ^^^^^^^^^^^^^^^^^^^^^^^
  File "/Users/amee/erpnext-bench/apps/frappe/frappe/utils/scheduler.py", line 143, in is_scheduler_inactive
    if is_scheduler_disabled(verbose=verbose):
       ^^^^^^^^^^^^^^^^^^^^^^^^^^^^^^^^^^^^^^
  File "/Users/amee/erpnext-bench/apps/frappe/frappe/utils/scheduler.py", line 156, in is_scheduler_disabled
    frappe.db.get_single_value("System Settings", "enable_scheduler")
  File "/Users/amee/erpnext-bench/apps/frappe/frappe/database/database.py", line 837, in get_single_value
    ).run()
      ^^^^^
  File "/Users/amee/erpnext-bench/apps/frappe/frappe/query_builder/utils.py", line 87, in execute_query
    result = frappe.db.sql(query, params, *args, **kwargs)  # nosemgrep
             ^^^^^^^^^^^^^^^^^^^^^^^^^^^^^^^^^^^^^^^^^^^^^
  File "/Users/amee/erpnext-bench/apps/frappe/frappe/database/database.py", line 207, in sql
    self.connect()
  File "/Users/amee/erpnext-bench/apps/frappe/frappe/database/database.py", line 112, in connect
    self._conn: "MariadbConnection" | "PostgresConnection" = self.get_connection()
                                                             ^^^^^^^^^^^^^^^^^^^^^
  File "/Users/amee/erpnext-bench/apps/frappe/frappe/database/mariadb/database.py", line 108, in get_connection
    conn = self._get_connection()
           ^^^^^^^^^^^^^^^^^^^^^^
  File "/Users/amee/erpnext-bench/apps/frappe/frappe/database/mariadb/database.py", line 114, in _get_connection
    return self.create_connection()
           ^^^^^^^^^^^^^^^^^^^^^^^^
  File "/Users/amee/erpnext-bench/apps/frappe/frappe/database/mariadb/database.py", line 117, in create_connection
    return pymysql.connect(**self.get_connection_settings())
           ^^^^^^^^^^^^^^^^^^^^^^^^^^^^^^^^^^^^^^^^^^^^^^^^^
  File "/Users/amee/erpnext-bench/env/lib/python3.11/site-packages/pymysql/connections.py", line 361, in __init__
    self.connect()
  File "/Users/amee/erpnext-bench/env/lib/python3.11/site-packages/pymysql/connections.py", line 668, in connect
    self._get_server_information()
  File "/Users/amee/erpnext-bench/env/lib/python3.11/site-packages/pymysql/connections.py", line 1098, in _get_server_information
    packet = self._read_packet()
             ^^^^^^^^^^^^^^^^^^^
  File "/Users/amee/erpnext-bench/env/lib/python3.11/site-packages/pymysql/connections.py", line 744, in _read_packet
    packet_header = self._read_bytes(4)
                    ^^^^^^^^^^^^^^^^^^^
  File "/Users/amee/erpnext-bench/env/lib/python3.11/site-packages/pymysql/connections.py", line 798, in _read_bytes
    raise err.OperationalError(
pymysql.err.OperationalError: (2013, 'Lost connection to MySQL server during query')
2025-07-15 16:30:24,103 ERROR scheduler Exception in Enqueue Events for Site erp.amey.local
Traceback (most recent call last):
  File "/Users/amee/erpnext-bench/apps/frappe/frappe/utils/scheduler.py", line 99, in enqueue_events_for_site
    if is_scheduler_inactive():
       ^^^^^^^^^^^^^^^^^^^^^^^
  File "/Users/amee/erpnext-bench/apps/frappe/frappe/utils/scheduler.py", line 143, in is_scheduler_inactive
    if is_scheduler_disabled(verbose=verbose):
       ^^^^^^^^^^^^^^^^^^^^^^^^^^^^^^^^^^^^^^
  File "/Users/amee/erpnext-bench/apps/frappe/frappe/utils/scheduler.py", line 156, in is_scheduler_disabled
    frappe.db.get_single_value("System Settings", "enable_scheduler")
  File "/Users/amee/erpnext-bench/apps/frappe/frappe/database/database.py", line 837, in get_single_value
    ).run()
      ^^^^^
  File "/Users/amee/erpnext-bench/apps/frappe/frappe/query_builder/utils.py", line 87, in execute_query
    result = frappe.db.sql(query, params, *args, **kwargs)  # nosemgrep
             ^^^^^^^^^^^^^^^^^^^^^^^^^^^^^^^^^^^^^^^^^^^^^
  File "/Users/amee/erpnext-bench/apps/frappe/frappe/database/database.py", line 207, in sql
    self.connect()
  File "/Users/amee/erpnext-bench/apps/frappe/frappe/database/database.py", line 112, in connect
    self._conn: "MariadbConnection" | "PostgresConnection" = self.get_connection()
                                                             ^^^^^^^^^^^^^^^^^^^^^
  File "/Users/amee/erpnext-bench/apps/frappe/frappe/database/mariadb/database.py", line 108, in get_connection
    conn = self._get_connection()
           ^^^^^^^^^^^^^^^^^^^^^^
  File "/Users/amee/erpnext-bench/apps/frappe/frappe/database/mariadb/database.py", line 114, in _get_connection
    return self.create_connection()
           ^^^^^^^^^^^^^^^^^^^^^^^^
  File "/Users/amee/erpnext-bench/apps/frappe/frappe/database/mariadb/database.py", line 117, in create_connection
    return pymysql.connect(**self.get_connection_settings())
           ^^^^^^^^^^^^^^^^^^^^^^^^^^^^^^^^^^^^^^^^^^^^^^^^^
  File "/Users/amee/erpnext-bench/env/lib/python3.11/site-packages/pymysql/connections.py", line 361, in __init__
    self.connect()
  File "/Users/amee/erpnext-bench/env/lib/python3.11/site-packages/pymysql/connections.py", line 668, in connect
    self._get_server_information()
  File "/Users/amee/erpnext-bench/env/lib/python3.11/site-packages/pymysql/connections.py", line 1098, in _get_server_information
    packet = self._read_packet()
             ^^^^^^^^^^^^^^^^^^^
  File "/Users/amee/erpnext-bench/env/lib/python3.11/site-packages/pymysql/connections.py", line 744, in _read_packet
    packet_header = self._read_bytes(4)
                    ^^^^^^^^^^^^^^^^^^^
  File "/Users/amee/erpnext-bench/env/lib/python3.11/site-packages/pymysql/connections.py", line 798, in _read_bytes
    raise err.OperationalError(
pymysql.err.OperationalError: (2013, 'Lost connection to MySQL server during query')
2025-07-15 16:33:24,608 ERROR scheduler Exception in Enqueue Events for Site erp.amey.local
Traceback (most recent call last):
  File "/Users/amee/erpnext-bench/apps/frappe/frappe/utils/scheduler.py", line 99, in enqueue_events_for_site
    if is_scheduler_inactive():
       ^^^^^^^^^^^^^^^^^^^^^^^
  File "/Users/amee/erpnext-bench/apps/frappe/frappe/utils/scheduler.py", line 143, in is_scheduler_inactive
    if is_scheduler_disabled(verbose=verbose):
       ^^^^^^^^^^^^^^^^^^^^^^^^^^^^^^^^^^^^^^
  File "/Users/amee/erpnext-bench/apps/frappe/frappe/utils/scheduler.py", line 156, in is_scheduler_disabled
    frappe.db.get_single_value("System Settings", "enable_scheduler")
  File "/Users/amee/erpnext-bench/apps/frappe/frappe/database/database.py", line 837, in get_single_value
    ).run()
      ^^^^^
  File "/Users/amee/erpnext-bench/apps/frappe/frappe/query_builder/utils.py", line 87, in execute_query
    result = frappe.db.sql(query, params, *args, **kwargs)  # nosemgrep
             ^^^^^^^^^^^^^^^^^^^^^^^^^^^^^^^^^^^^^^^^^^^^^
  File "/Users/amee/erpnext-bench/apps/frappe/frappe/database/database.py", line 207, in sql
    self.connect()
  File "/Users/amee/erpnext-bench/apps/frappe/frappe/database/database.py", line 112, in connect
    self._conn: "MariadbConnection" | "PostgresConnection" = self.get_connection()
                                                             ^^^^^^^^^^^^^^^^^^^^^
  File "/Users/amee/erpnext-bench/apps/frappe/frappe/database/mariadb/database.py", line 108, in get_connection
    conn = self._get_connection()
           ^^^^^^^^^^^^^^^^^^^^^^
  File "/Users/amee/erpnext-bench/apps/frappe/frappe/database/mariadb/database.py", line 114, in _get_connection
    return self.create_connection()
           ^^^^^^^^^^^^^^^^^^^^^^^^
  File "/Users/amee/erpnext-bench/apps/frappe/frappe/database/mariadb/database.py", line 117, in create_connection
    return pymysql.connect(**self.get_connection_settings())
           ^^^^^^^^^^^^^^^^^^^^^^^^^^^^^^^^^^^^^^^^^^^^^^^^^
  File "/Users/amee/erpnext-bench/env/lib/python3.11/site-packages/pymysql/connections.py", line 361, in __init__
    self.connect()
  File "/Users/amee/erpnext-bench/env/lib/python3.11/site-packages/pymysql/connections.py", line 669, in connect
    self._request_authentication()
  File "/Users/amee/erpnext-bench/env/lib/python3.11/site-packages/pymysql/connections.py", line 957, in _request_authentication
    auth_packet = self._read_packet()
                  ^^^^^^^^^^^^^^^^^^^
  File "/Users/amee/erpnext-bench/env/lib/python3.11/site-packages/pymysql/connections.py", line 775, in _read_packet
    packet.raise_for_error()
  File "/Users/amee/erpnext-bench/env/lib/python3.11/site-packages/pymysql/protocol.py", line 219, in raise_for_error
    err.raise_mysql_exception(self._data)
  File "/Users/amee/erpnext-bench/env/lib/python3.11/site-packages/pymysql/err.py", line 150, in raise_mysql_exception
    raise errorclass(errno, errval)
pymysql.err.OperationalError: (1045, "Access denied for user '_06a502cd4c3d610c'@'localhost' (using password: YES)")
2025-07-15 16:34:24,635 ERROR scheduler Exception in Enqueue Events for Site erp.amey.local
Traceback (most recent call last):
  File "/Users/amee/erpnext-bench/apps/frappe/frappe/utils/scheduler.py", line 99, in enqueue_events_for_site
    if is_scheduler_inactive():
       ^^^^^^^^^^^^^^^^^^^^^^^
  File "/Users/amee/erpnext-bench/apps/frappe/frappe/utils/scheduler.py", line 143, in is_scheduler_inactive
    if is_scheduler_disabled(verbose=verbose):
       ^^^^^^^^^^^^^^^^^^^^^^^^^^^^^^^^^^^^^^
  File "/Users/amee/erpnext-bench/apps/frappe/frappe/utils/scheduler.py", line 156, in is_scheduler_disabled
    frappe.db.get_single_value("System Settings", "enable_scheduler")
  File "/Users/amee/erpnext-bench/apps/frappe/frappe/database/database.py", line 837, in get_single_value
    ).run()
      ^^^^^
  File "/Users/amee/erpnext-bench/apps/frappe/frappe/query_builder/utils.py", line 87, in execute_query
    result = frappe.db.sql(query, params, *args, **kwargs)  # nosemgrep
             ^^^^^^^^^^^^^^^^^^^^^^^^^^^^^^^^^^^^^^^^^^^^^
  File "/Users/amee/erpnext-bench/apps/frappe/frappe/database/database.py", line 207, in sql
    self.connect()
  File "/Users/amee/erpnext-bench/apps/frappe/frappe/database/database.py", line 112, in connect
    self._conn: "MariadbConnection" | "PostgresConnection" = self.get_connection()
                                                             ^^^^^^^^^^^^^^^^^^^^^
  File "/Users/amee/erpnext-bench/apps/frappe/frappe/database/mariadb/database.py", line 108, in get_connection
    conn = self._get_connection()
           ^^^^^^^^^^^^^^^^^^^^^^
  File "/Users/amee/erpnext-bench/apps/frappe/frappe/database/mariadb/database.py", line 114, in _get_connection
    return self.create_connection()
           ^^^^^^^^^^^^^^^^^^^^^^^^
  File "/Users/amee/erpnext-bench/apps/frappe/frappe/database/mariadb/database.py", line 117, in create_connection
    return pymysql.connect(**self.get_connection_settings())
           ^^^^^^^^^^^^^^^^^^^^^^^^^^^^^^^^^^^^^^^^^^^^^^^^^
  File "/Users/amee/erpnext-bench/env/lib/python3.11/site-packages/pymysql/connections.py", line 361, in __init__
    self.connect()
  File "/Users/amee/erpnext-bench/env/lib/python3.11/site-packages/pymysql/connections.py", line 669, in connect
    self._request_authentication()
  File "/Users/amee/erpnext-bench/env/lib/python3.11/site-packages/pymysql/connections.py", line 957, in _request_authentication
    auth_packet = self._read_packet()
                  ^^^^^^^^^^^^^^^^^^^
  File "/Users/amee/erpnext-bench/env/lib/python3.11/site-packages/pymysql/connections.py", line 775, in _read_packet
    packet.raise_for_error()
  File "/Users/amee/erpnext-bench/env/lib/python3.11/site-packages/pymysql/protocol.py", line 219, in raise_for_error
    err.raise_mysql_exception(self._data)
  File "/Users/amee/erpnext-bench/env/lib/python3.11/site-packages/pymysql/err.py", line 150, in raise_mysql_exception
    raise errorclass(errno, errval)
pymysql.err.OperationalError: (1045, "Access denied for user '_06a502cd4c3d610c'@'localhost' (using password: YES)")
